Workbook

Sheet Key Assumptions
A1: HUBSTOR → AWS S3 MIGRATION | KEY ASSUMPTIONS & CAVEATS
A2: These assumptions must be reviewed and validated before the migration programme is formally approved. Any change to these assumptions may materially affect costs, timelines, or feasibility.
A4: BUSINESS & SCOPE ASSUMPTIONS
A5: # | B5: Assumption | C5: Detail & Implication | D5: Status / Action Required
A6: A1 | B6: HubStor advanced features NOT included in new architecture | C6: We have NOT replicated HubStor-specific features such as content indexing, advanced discovery, legal hold workflow, or smart tiering intelligence. These are excluded because it is currently UNKNOWN whether these features are actively used by any CRL site or user. If any site relies on these features, additional tooling (e.g. AWS OpenSearch, Elasticsearch, or a third-party discovery layer) would need to be scoped and costed separately. | D6: ⚠ Validate with site leads before migration start
A7: A2 | B7: Discovery sites: potential divestitures not modelled | C7: CONFIRMED: All European Discovery sites (CRP, HAR, PTH — UK; LEI, GRO, KUO, SZG — NL/EU; FRI — DE) will be transferred to the new company environment from January 2027 onwards. These sites account for 70% of total data (746,609 GiB) and $24,807/mo of HubStor cost. Their data will NOT be migrated to AWS S3. CRL will bear the Azure retrieval and egress cost ($86,843 total) to export the data for hand-off. The timeline is: Jan=CRP, Feb=LEI, Mar=KUO+FRI, Apr=PTH+HAR, May=GRO+SZG, fully complete by Jun 2027. AWS S3 will only store non-discovery data: Safety Assessment, Microbial, and RMS sites (320,095 GiB). | D7: ✅ CONFIRMED — Discovery data → new company from Jan 2027
A8: A3 | B8: Contractual obligations & data retention policy not yet verified | C8: We have assumed a 6-month migration window (Jul–Dec 2026) and HubStor termination from Jan 2027. HOWEVER: HubStor's contract notice period, any early termination penalties, and site-specific data retention policies (e.g. regulatory holds, litigation hold) have NOT been formally reviewed. These may affect: (1) the earliest possible HubStor termination date, (2) which data can be deleted from Azure and when, and (3) minimum retention periods before data can be moved. Legal and compliance review MUST be completed before finalising the migration schedule. | D8: 🔴 CRITICAL — Legal/Compliance review required BEFORE approval
A9: A4 | B9: HubStor not used for regulated / validated GxP systems | C9: This analysis assumes HubStor does not hold data from GxP-regulated or computer-system-validated environments. If HubStor IS used as part of a validated system (e.g. LIMS, ELN, laboratory instrument data), then: (1) migration must follow a validated CSV/change control process, (2) IQ/OQ/PQ testing may be required, (3) migration timelines will extend significantly, and (4) QA/Regulatory sign-off is mandatory before cutover. Please confirm with QA, Regulatory, and IT Compliance that no validated systems write to HubStor. | D9: 🔴 CRITICAL — QA/Regulatory confirmation required
A10: A5 | B10: All migration work performed by CRL internal resources (no external vendor) | C10: The cost model includes ZERO external vendor or consultancy fees. All activities — AWS account setup, IAM configuration, Storage Gateway installation, DataSync migration jobs, connector testing, validation, and HubStor decommission — are assumed to be executed by CRL's internal Cloud/IT team. If external resource is required (e.g. AWS Professional Services, system integrator, or HubStor migration support), an additional cost of $50K–$150K should be budgeted. Internal resource time has not been separately costed (opportunity cost only). | D10: ⚠ Confirm internal resource availability before commitment
A11: A6 | B11: Azure Backup & DataBox: $3,000/mo additional charge included | C11: An additional $3,000/month Azure charge for Backup services and DataBox has been identified and IS included in this analysis as a separate line item in the current cost. This charge ceases when Azure is fully decommissioned (Dec 2026). It increases the true current Azure cost baseline and therefore increases the monthly saving. | D11: ✅ Included in cost model — verified $3,000/mo
A12: A7 | B12: AWS costs held flat for Year 1 (2027); 5% growth from Year 2 (2028) | C12: AWS storage and infrastructure pricing is assumed constant in 2027 (no growth). From 2028 onwards, data volume grows at 5% per year (conservative), increasing S3 storage costs. AWS list prices are not assumed to increase. Gateway appliance cost is amortised over 36 months. | D12: ✅ Conservative growth assumption
A13: A8 | B13: Storage Gateway: Hardware Appliance model selected | C13: Architecture assumes the AWS Storage Gateway Hardware Appliance (physical unit purchased/leased per site) rather than a VM-based software gateway. Cost modelled at ~$470/site/mo (amortised over 36 months from ~$16,920 list price). No EC2 instances or EBS volumes are required. If VM-based gateway on existing on-prem server is used instead, gateway cost = $0 (software only). | D13: ⚠ Confirm hardware vs VM gateway with each site
A14: A9
A15: This document is prepared for internal CRL review only. Costs are estimates based on published list pricing as of Q1 2026 and actual HubStor Master Report data. Final costs subject to AWS contract negotiations, Wasabi quote, and HubStor termination terms. Not for external distribution.

Sheet Assumptions
A1: CENTRAL ASSUMPTIONS — ALL INPUTS IN ONE PLACE
A2: Yellow = hardcoded inputs (change here) | All other sheets reference these cells | Black text = formula | Blue text = linked input
A4: STORAGE VOLUMES (from HubStor Master Report v5)
A5: Parameter | B5: Cell Ref | C5: Value | D5: Unit | E5: Source / Notes
A6: Standard tier GiB | B6: A6 | C6: 0 | D6: GiB | E6: HubStor Master Report v5 actuals
A7: Hot tier GiB | B7: A7 | C7: 4887.87 | D7: GiB | E7: HubStor Master Report v5 actuals
A8: Cool tier GiB | B8: A8 | C8: 14645.59 | D8: GiB | E8: HubStor Master Report v5 actuals
A9: Cold tier GiB | B9: A9 | C9: 0 | D9: GiB | E9: HubStor Master Report v5 actuals
A10: Archive tier GiB | B10: A10 | C10: 300561.87 | D10: GiB | E10: HubStor Master Report v5 actuals
A11: GiB → GB conversion factor | B11: A11 | C11: 1.074 | D11: × | E11: 1 GiB = 1.074 GB (decimal)
A12: GiB per TiB (divisor) | B12: A12 | C12: 1024 | D12: ÷ | E12: 1 TiB = 1024 GiB
A13: Total GiB (all tiers) | B13: A13 | C13: =C6+C7+C8+C9+C10 -> 320095.33 | D13: GiB | E13: Sum of all five tiers
A14: Total TiB | B14: A14 | C14: =C13/C12 -> 312.5931 | D14: TiB | E14: Total GiB ÷ 1,024
A15: Total GB (decimal) | B15: A15 | C15: =C13*C11 -> 343782.38 | D15: GB | E15: Total GiB × 1.074 (for Azure/AWS pricing which uses decimal GB)
A16: US region GiB | B16: A16 | C16: =221472.95+72998.02 -> 294470.97 | D16: GiB | E16: EastUS2 + WestUS2 (from Master Report)
A17: EU region GiB | B17: A17 | C17: =374040.18+349749.29+48444.2 -> 772233.67 | D17: GiB | E17: UKSouth + WestEurope + GermanyWestCentral
A18: US region GB | B18: A18 | C18: =C16*C11 -> 316261.82 | D18: GB | E18: US GiB × 1.074
A19: EU region GB | B19: A19 | C19: =C17*C11 -> 829378.96 | D19: GB | E19: EU GiB × 1.074
A21: AZURE / HUBSTOR PRICING
A22: Parameter | B22: Cell Ref | C22: Value | D22: Unit | E22: Source / Notes
A23: Azure Standard/Hot $/GB/mo | B23: A23 | C23: 0.02 | D23: $/GB/mo | E23: Azure Blob Standard pricing (public)
A24: Azure Cool $/GB/mo | B24: A24 | C24: 0.015 | D24: $/GB/mo | E24: Azure Blob Cool tier
A25: Azure Cold $/GB/mo | B25: A25 | C25: 0.01 | D25: $/GB/mo | E25: Azure Blob Cold tier
A26: Azure Archive $/GB/mo | B26: A26 | C26: 0.002 | D26: $/GB/mo | E26: Azure Blob Archive tier
A27: HubStor mgmt fee % of storage | B27: A27 | C27: 0.3428 | D27: % | E27: Actual ratio: $9,068 non-storage ÷ $26,455 storage from Master Report
A28: Azure Cool retrieval $/GB | B28: A28 | C28: 0.01 | D28: $/GB | E28: Azure Blob Cool read charge
A29: Azure Cold retrieval $/GB | B29: A29 | C29: 0.03 | D29: $/GB | E29: Azure Blob Cold read charge
A30: Azure Archive rehydration $/GB | B30: A30 | C30: 0.022 | D30: $/GB | E30: Standard rehydration priority (~15hr wait)
A31: Azure egress tier1 $/GB | B31: A31 | C31: 0.087 | D31: $/GB | E31: 0–10 TB internet egress
A32: Azure egress tier2 $/GB | B32: A32 | C32: 0.083 | D32: $/GB | E32: 10–50 TB internet egress
A33: Azure egress tier3 $/GB | B33: A33 | C33: 0.07 | D33: $/GB | E33: 50–150 TB internet egress
A34: Azure egress tier4 $/GB | B34: A34 | C34: 0.05 | D34: $/GB | E34: >150 TB internet egress
A36: AWS PRICING
A37: Parameter | B37: Cell Ref | C37: Value | D37: Unit | E37: Source / Notes
A38: S3 Standard $/GB/mo (US) | B38: A38 | C38: 0.023 | D38: $/GB/mo | E38: AWS us-east-1 list price 2026
A39: S3 Standard $/GB/mo (EU) | B39: A39 | C39: 0.024 | D39: $/GB/mo | E39: AWS EU regions list price
A40: S3 Standard-IA $/GB/mo (US) | B40: A40 | C40: 0.0125 | D40: $/GB/mo | E40: AWS Standard-IA storage rate
A41: S3 Standard-IA $/GB/mo (EU) | B41: A41 | C41: 0.013 | D41: $/GB/mo | E41: AWS EU Standard-IA
A42: S3 Glacier IR $/GB/mo (US) | B42: A42 | C42: 0.004 | D42: $/GB/mo | E42: Glacier Instant Retrieval
A43: S3 Glacier IR $/GB/mo (EU) | B43: A43 | C43: 0.0045 | D43: $/GB/mo | E43: Glacier IR EU
...

Sheet Executive Summary
A1: HUBSTOR → AWS S3 COMPLETE MIGRATION | BUSINESS CASE & COST ANALYSIS
A2: Prepared for Internal Review | Based on HubStor Master Report v5 | Full HubStor + Azure Blob replacement
A4: FULL CURRENT COST (HubStor all sites + Backup/DataBox) | D4: AWS TOTAL MONTHLY (non-discovery S3 only — from Jul 2027) | G4: FULL STEADY-STATE SAVING (from Jul 2027 — all migration complete) | J4: TOTAL MIGRATION COST (Phase 1 non-disc + Phase 2 discovery)
A5: =Assumptions!C65+Assumptions!C66+Assumptions!C67 -> 38523.12 | D5: ='Cost Comparison'!B39 -> 2291.1038 | G5: =Assumptions!C65+Assumptions!C66+Assumptions!C67-'Cost Comparison'!B39 -> 36232.016 | J5: ='Migration Plan & Costs'!C60+SUM('Financial Model (Jun26-Dec30)'!F30:F35) -> 131953.28
A6: ="$"&TEXT((Assumptions!C65+Assumptions!C66+Assumptions!C67)*12,"#,##0")&"/yr | HubStor $35,523 + Backup $3,000 | 1,042 TiB | 5 regions" -> $462,277/yr | HubStor $35,523 + Backup $3,000 | 1,042 TiB | 5 regions | D6: ="$"&TEXT('Cost Comparison'!B39*12,"#,##0")&"/yr | 320,095 GiB | S3 + 3 Gateway appliances" -> $27,493/yr | 320,095 GiB | S3 + 3 Gateway appliances | G6: ="$"&TEXT((Assumptions!C65+Assumptions!C66+Assumptions!C67-'Cost Comparison'!B39)*12,"#,##0")&"/yr saved | 86.7% reduction | Realised from Jul 2027" -> $434,784/yr saved | 86.7% reduction | Realised from Jul 2027 | J6: ="Phase 1 (non-disc to S3): ~$51,203 + Phase 2 (disc hand-off): ~$86,843 = ~$138,047 total" -> Phase 1 (non-disc to S3): ~$51,203 + Phase 2 (disc hand-off): ~$86,843 = ~$138,047 total
A7: 📌 ARCHITECTURE CHANGE: Discovery sites (746,609 GiB, 70% of data) will NOT be stored in AWS S3. They are handed off to a new company environment Jan–Jun 2027. AWS S3 stores non-discovery data only (320,095 GiB). Full saving of $36,232/mo realised from Jul 2027 once all HubStor and Azure charges cease.
A8: CURRENT HUBSTOR COSTS BY AZURE REGION (Source: HubStor Master Report v5)
A9: Azure Region | B9: Azure Location | C9: Total Usage (GiB) | D9: Formula: GiB | E9: Storage Cost/mo ($) | F9: Non-Storage/HubStor Fee ($) | G9: Total Cost/mo ($) | H9: Formula: Total
A10: EastUS2 | B10: Virginia, USA | C10: 221472.95 | D10: Hardcoded from Master Report | E10: 5798.59 | F10: 1882.71 | G10: =E10+F10 -> 7681.3 | H10: Storage + HubStor platform/non-storage fee
A11: GermanyWestCentral | B11: Frankfurt, Germany | C11: 48444.2 | D11: Hardcoded from Master Report | E11: 1337.27 | F11: 411.82 | G11: =E11+F11 -> 1749.09 | H11: Storage + HubStor platform/non-storage fee
A12: UKSouth | B12: London, UK | C12: 374040.18 | D12: Hardcoded from Master Report | E12: 9432.17 | F12: 3179.68 | G12: =E12+F12 -> 12611.85 | H12: Storage + HubStor platform/non-storage fee
A13: WestEurope | B13: Amsterdam, Netherlands | C13: 349749.29 | D13: Hardcoded from Master Report | E13: 8299.36 | F13: 2973.19 | G13: =E13+F13 -> 11272.55 | H13: Storage + HubStor platform/non-storage fee
A14: WestUS2 | B14: Washington, USA | C14: 72998.02 | D14: Hardcoded from Master Report | E14: 1587.78 | F14: 620.55 | G14: =E14+F14 -> 2208.33 | H14: Storage + HubStor platform/non-storage fee
A15: GRAND TOTAL | B15: All 5 Azure Regions | C15: =SUM(C10:C14) -> 1066704.6 | D15: SUM(C10:C14) — sum all regions | E15: =SUM(E10:E14) -> 26455.17 | F15: =SUM(F10:F14) -> 9067.95 | G15: =SUM(G10:G14) -> 35523.12 | H15: Storage Cost + Non-Storage/HubStor platform fee
A17: STORAGE BY AZURE TIER (all values from Assumptions sheet — change inputs there)
A18: Azure Tier | B18: Equiv. AWS Class | C18: Usage (GiB) | D18: Usage (TiB) | E18: % of Total | F18: Azure $/GB/mo
A19: Standard | B19: S3 Standard | C19: =Assumptions!C6 -> 0 | D19: =C19/1024 -> 0 | E19: =C19/Assumptions!C13 -> 0 | F19: =Assumptions!C23 -> 0.02
A20: Hot | B20: S3 Standard | C20: =Assumptions!C7 -> 4887.87 | D20: =C20/1024 -> 4.7733105 | E20: =C20/Assumptions!C13 -> 0.015270045 | F20: =Assumptions!C23 -> 0.02
A21: Cool | B21: S3 Standard-IA | C21: =Assumptions!C8 -> 14645.59 | D21: =C21/1024 -> 14.302334 | E21: =C21/Assumptions!C13 -> 0.045753838 | F21: =Assumptions!C24 -> 0.015
A22: Cold | B22: S3 Glacier IR | C22: =Assumptions!C9 -> 0 | D22: =C22/1024 -> 0 | E22: =C22/Assumptions!C13 -> 0 | F22: =Assumptions!C25 -> 0.01
A23: Archive | B23: S3 Deep Archive | C23: =Assumptions!C10 -> 300561.87 | D23: =C23/1024 -> 293.51745 | E23: =C23/Assumptions!C13 -> 0.93897612 | F23: =Assumptions!C26 -> 0.002
A24: TOTAL | C24: =Assumptions!C13 -> 320095.33 | D24: =C24/1024 -> 312.5931 | E24: =SUM(E19:E23) -> 1

Sheet Cost Comparison
A1: AZURE HUBSTOR vs AWS S3 — COMPLETE COST COMPARISON (Storage + All Infrastructure)
A2: All values linked to Assumptions sheet | Black = formula | Blue = hardcoded input | Green = cross-sheet link | Yellow = input cell
A4: TIER PRICING ASSUMPTIONS (all rates from Assumptions sheet — edit there)
A5: Storage Tier | B5: Azure Tier | C5: Azure $/GB/mo | D5: Formula | E5: AWS Class | F5: AWS $/GB/mo (blended) | G5: Formula | H5: HubStor Mgmt % | I5: Formula | J5: Min Duration | K5: Notes
A6: Standard/Hot | B6: Standard/Hot | C6: =Assumptions!C23 -> 0.02 | D6: =Assumptions!C22 -> Value | E6: S3 Standard | F6: =(Assumptions!C38+Assumptions!C39)/2 -> 0.0235 | G6: (Assumptions!C36+Assumptions!C37)/2 — avg US+EU | H6: =Assumptions!C27 -> 0.3428 | I6: =Assumptions!C26 -> 0.002 | J6: None | K6: Active files; low % of total
A7: Cool | B7: Cool | C7: =Assumptions!C24 -> 0.015 | D7: =Assumptions!C23 -> 0.02 | E7: S3 Standard-IA | F7: =(Assumptions!C40+Assumptions!C41)/2 -> 0.01275 | G7: =(Assumptions!C38+Assumptions!C39)/2 -> 0.0235 | H7: =Assumptions!C27 -> 0.3428 | I7: =Assumptions!C26 -> 0.002 | J7: 30 days | K7: Retrieval fee applies
A8: Cold | B8: Cold | C8: =Assumptions!C25 -> 0.01 | D8: =Assumptions!C24 -> 0.015 | E8: S3 Glacier IR | F8: =(Assumptions!C42+Assumptions!C43)/2 -> 0.00425 | G8: =(Assumptions!C40+Assumptions!C41)/2 -> 0.01275 | H8: =Assumptions!C27 -> 0.3428 | I8: =Assumptions!C26 -> 0.002 | J8: 90 days | K8: Millisecond retrieval
A9: Archive | B9: Archive | C9: =Assumptions!C26 -> 0.002 | D9: =Assumptions!C25 -> 0.01 | E9: S3 Deep Archive | F9: =(Assumptions!C44+Assumptions!C45)/2 -> 0.000995 | G9: =(Assumptions!C42+Assumptions!C43)/2 -> 0.00425 | H9: =Assumptions!C27 -> 0.3428 | I9: =Assumptions!C26 -> 0.002 | J9: 180 days | K9: Dominant tier — 83% of data
A11: ⚠ NOTE: AWS S3 storage costs below reflect NON-DISCOVERY sites only (Safety Assessment, Microbial, RMS = 320,095 GiB). Discovery sites (746,609 GiB) are NOT stored in AWS S3 — they are handed off to the new company Jan–Jun 2027. The HubStor baseline in the summary section reflects the full current cost ($38,523/mo) as the comparison baseline.
A12: Tier | B12: Usage (GiB) | C12: Usage (TiB) | D12: Formula: TiB | E12: Azure Storage $/mo | F12: Formula | G12: HubStor Mgmt $/mo | H12: Formula | I12: Azure Total $/mo | J12: Formula | K12: AWS Storage $/mo | L12: Formula | M12: Monthly Saving $ | N12: Formula
A13: Standard/Hot | B13: =Assumptions!C6+Assumptions!C7 -> 4887.87 | C13: =B13/1024 -> 4.7733105 | D13: B13÷1024 | E13: =B13*Assumptions!C11*Assumptions!C23 -> 104.99145 | F13: B13×Assumptions CC23×1.074 (GiB→GB×$/GB) | G13: =E13*Assumptions!C27 -> 35.991068 | H13: azure storage × HubStor mgmt% | I13: =E13+G13 -> 140.98252 | J13: azure storage + hubstor mgmt fee | K13: =B13*Assumptions!C11*(Assumptions!C38+Assumptions!C39)/2 -> 123.36495 | L13: B13×1.074×Blended Standard/Hot AWS price | M13: =I13-K13 -> 17.617565 | N13: Azure Total - AWS Storage = monthly saving
A14: Cool | B14: =Assumptions!C8 -> 14645.59 | C14: =B14/1024 -> 14.302334 | D14: B14÷1024 | E14: =B14*Assumptions!C11*Assumptions!C24 -> 235.94045 | F14: B14×Assumptions CC24×1.074 (GiB→GB×$/GB) | G14: =E14*Assumptions!C27 -> 80.880388 | H14: azure storage × HubStor mgmt% | I14: =E14+G14 -> 316.82084 | J14: azure storage + hubstor mgmt fee | K14: =B14*Assumptions!C11*(Assumptions!C40+Assumptions!C41)/2 -> 200.54939 | L14: B14×1.074×Standard-IA blended | M14: =I14-K14 -> 116.27146 | N14: Azure Total - AWS Storage = monthly saving
A15: Cold | B15: =Assumptions!C9 -> 0 | C15: =B15/1024 -> 0 | D15: B15÷1024 | E15: =B15*Assumptions!C11*Assumptions!C25 -> 0 | F15: B15×Assumptions CC25×1.074 (GiB→GB×$/GB) | G15: =E15*Assumptions!C27 -> 0 | H15: azure storage × HubStor mgmt% | I15: =E15+G15 -> 0 | J15: azure storage + hubstor mgmt fee | K15: =B15*Assumptions!C11*(Assumptions!C42+Assumptions!C43)/2 -> 0 | L15: B15×1.074×Glacier IR blended | M15: =I15-K15 -> 0 | N15: Azure Total - AWS Storage = monthly saving
A16: Archive | B16: =Assumptions!C10 -> 300561.87 | C16: =B16/1024 -> 293.51745 | D16: B16÷1024 | E16: =B16*Assumptions!C11*Assumptions!C26 -> 645.6069 | F16: B16×Assumptions CC26×1.074 (GiB→GB×$/GB) | G16: =E16*Assumptions!C27 -> 221.31404 | H16: azure storage × HubStor mgmt% | I16: =E16+G16 -> 866.92094 | J16: azure storage + hubstor mgmt fee | K16: =B16*Assumptions!C11*(Assumptions!C44+Assumptions!C45)/2 -> 321.18943 | L16: B16×1.074×Glacier Deep Archive blended | M16: =I16-K16 -> 545.73151 | N16: Azure Total - AWS Storage = monthly saving
A17: STORAGE SUBTOTAL | B17: =SUM(B13:B16) -> 320095.33 | C17: =SUM(C13:C16) -> 312.5931 | E17: =SUM(E13:E16) -> 986.5388 | G17: =SUM(G13:G16) -> 338.1855 | I17: =SUM(I13:I16) -> 1324.7243 | K17: =SUM(K13:K16) -> 645.10377 | M17: =SUM(M13:M16) -> 679.62053
A19: AWS INFRASTRUCTURE COSTS — Storage Gateway Appliance Architecture (On-prem → Appliance → S3)
A20: Resource | B20: Qty | C20: Unit Cost /mo | D20: Monthly ($) | E20: Annual ($) | F20: Notes
A21: Storage Gateway Hardware Appliance (5 sites × amortised) | B21: =Assumptions!C54 -> 3 | C21: =Assumptions!C52 -> 470 | D21: =B21*C21 -> 1410 | E21: =D21*12 -> 16920 | F21: AWS-sold hardware appliance ~$16,920/unit ÷ 36mo = $470/site/mo. No EC2, no EBS needed.
A22: S3 Transfer Acceleration (optional — set $0 for archive) | B22: 1 | C22: =Assumptions!C53 -> 0 | D22: =B22*C22 -> 0 | E22: =D22*12 -> 0 | F22: Only needed if upload speed over long-distance WAN is critical. Archive workloads: $0.
A23: CloudWatch (monitoring, dashboards, alarms, logs) | B23: 1 | C23: =Assumptions!C55 -> 31 | D23: =B23*C23 -> 31 | E23: =D23*12 -> 372 | F23: Dashboards + custom metrics + CloudWatch alarms + log ingestion
A24: AWS KMS — Customer Managed Keys (1 per region × 5) | B24: =Assumptions!C57 -> 3 | C24: =Assumptions!C56 -> 1 | D24: =B24*C24 -> 3 | E24: =D24*12 -> 36 | F24: $1/key/mo × 5 regions = $5/mo. Encrypts S3 objects and Gateway cache.
A25: SNS — cost & health alert notifications | B25: 1 | C25: =Assumptions!C58 -> 2 | D25: =B25*C25 -> 2 | E25: =D25*12 -> 24 | F25: Alert topics for budget anomalies and Gateway connectivity issues
A26: AWS Config — compliance rule evaluation | B26: 1 | C26: =Assumptions!C59 -> 10 | D26: =B26*C26 -> 10 | E26: =D26*12 -> 120 | F26: GxP/regulatory config rules on S3 buckets. Object Lock compliance checks.
A27: S3 API Operations — ongoing PUTs/GETs (new archive writes) | B27: 1 | C27: =Assumptions!C60 -> 65 | D27: =B27*C27 -> 65 | E27: =D27*12 -> 780 | F27: Estimated monthly API cost for new data written from all 5 gateway sites
A28: Glacier Deep Archive retrieval fees (ongoing, est. 0.5%/mo) | B28: 1 | C28: =Assumptions!C61 -> 86 | D28: =B28*C28 -> 86 | E28: =D28*12 -> 1032 | F28: 0.5% of 862 TiB retrieved/mo × $0.02/GB restore fee
A29: S3 egress to internet (end-user retrieval, est.) | B29: 1 | C29: =Assumptions!C62 -> 39 | D29: =B29*C29 -> 39 | E29: =D29*12 -> 468 | F29: ~10% of retrieved data sent externally. Rest served within AWS/Gateway.
A30: INFRASTRUCTURE SUBTOTAL | D30: =SUM(D21:D29) -> 1646 | E30: =SUM(E21:E29) -> 19752
A32: TOTAL COST SUMMARY — HUBSTOR (CURRENT) vs AWS S3 COMPLETE REPLACEMENT
A33: Line Item | B33: Monthly ($) | C33: Annual ($) | D33: Saving vs HubStor | E33: % Reduction | F33: Notes
A34: HubStor + Azure Blob Storage (from Master Report) | B34: =Assumptions!C65+Assumptions!C66 -> 35523.12 | C34: =(Assumptions!C65+Assumptions!C66)*12 -> 426277.44 | D34: $0 | E34: — | F34: Full HubStor from Master Report v5: non-disc $10,716 + discovery $24,807 = $35,523/mo total
A35: Azure Backup & DataBox (additional charge) | B35: =Assumptions!C67 -> 3000 | C35: =Assumptions!C67*12 -> 36000 | D35: $0 | E35: — | F35: Backup services + DataBox ($3,000/mo). Ceases Dec 2026 when Azure fully decommissioned.
A36: TOTAL CURRENT MONTHLY COST (ALL-IN) | B36: =B34+B35 -> 38523.12 | C36: =C34+C35 -> 462277.44 | D36: $0 | E36: Baseline for all saving calculations | F36: HubStor + Azure Blob + Backup/DataBox — this is what we actually pay today
A37: AWS S3 Storage Cost (all 5 tiers) | B37: =K17 -> 645.10377 | C37: =K17*12 -> 7741.2452 | D37: =B36-B37 -> 37878.016 | E37: =(B36-B37)/B36 -> 0.98325411 | F37: Non-disc S3 storage only (320,095 GiB). Discovery data NOT in S3.
A38: AWS Infrastructure (Gateway appliance + ops) | B38: =D30 -> 1646 | C38: =E30 -> 19752 | F38: 3 gateway appliances: US-East, US-West, EU-NL (non-disc sites only). No gateways for discovery sites.
A39: AWS TOTAL (Storage + Infrastructure) | B39: =B37+B38 -> 2291.1038 | C39: =C37+C38 -> 27493.245 | D39: =B36-B39 -> 36232.016 | E39: =(B36-B39)/B36 -> 0.94052653 | F39: Full saving realised from Jul 2027 when HubStor+Azure=$0 and only AWS non-disc remains.

Sheet Migration Plan & Costs
A1: ONE-TIME MIGRATION COSTS — COMPLETE ITEMIZED BREAKDOWN (All formulas shown)
A2: All four cost components + AWS setup costs | Black = formula | Blue/Yellow = input | Route: Azure → Public internet → S3 (NOT via VPN)
A4: COMPONENT 1 — AZURE RETRIEVAL CHARGES (reading data out of Azure Blob before egress)
A5: ℹ Standard/Hot: no retrieval fee. Cool=$0.01/GB. Cold=$0.03/GB. Archive=$0.022/GB (Standard rehydration, ~15hr wait — factor into timeline)
A6: Azure Tier | B6: GiB (input) | C6: GB (decimal) | D6: Formula: GB | E6: Retrieval $/GB | F6: Formula | G6: Retrieval Cost ($) | H6: Formula | I6: Notes
A7: Standard | B7: =Assumptions!C6 -> 0 | C7: =B7*Assumptions!C11 -> 0 | D7: B7×Assumptions!C11 (GiB→GB) | E7: 0 | F7: 0 | G7: 0 | H7: No charge — Standard tier: read freely at no cost | I7: No retrieval fee
A8: Hot | B8: =Assumptions!C7 -> 4887.87 | C8: =B8*Assumptions!C11 -> 5249.5724 | D8: B8×Assumptions!C11 (GiB→GB) | E8: 0 | F8: 0 | G8: 0 | H8: No charge — Hot tier: read freely at no cost | I8: No retrieval fee
A9: Cool | B9: =Assumptions!C8 -> 14645.59 | C9: =B9*Assumptions!C11 -> 15729.364 | D9: B9×Assumptions!C11 (GiB→GB) | E9: =Assumptions!C28 -> 0.01 | F9: =Assumptions!C28 -> 0.01 | G9: =C9*E9 -> 157.29364 | H9: C9×E9 (GB × retrieval rate) | I9: Per-GB read charge
A10: Cold | B10: =Assumptions!C9 -> 0 | C10: =B10*Assumptions!C11 -> 0 | D10: B10×Assumptions!C11 (GiB→GB) | E10: =Assumptions!C29 -> 0.03 | F10: =Assumptions!C29 -> 0.03 | G10: =C10*E10 -> 0 | H10: C10×E10 (GB × retrieval rate) | I10: Per-GB read charge
A11: Archive | B11: =Assumptions!C10 -> 300561.87 | C11: =B11*Assumptions!C11 -> 322803.45 | D11: B11×Assumptions!C11 (GiB→GB) | E11: =Assumptions!C30 -> 0.022 | F11: =Assumptions!C30 -> 0.022 | G11: =C11*E11 -> 7101.6759 | H11: C11×E11 (GB × retrieval rate) | I11: Standard rehydration rate (15hr per batch)
A12: SUBTOTAL — AZURE RETRIEVAL | G12: =SUM(G7:G11) -> 7258.9695 | H12: SUM(G7:G11) — sum all five tiers
A14: COMPONENT 2 — AZURE EGRESS CHARGES (direct to S3 public endpoint — NOT via VPN)
A15: ℹ VPN routing adds AWS transit/inspection costs. Use S3 public endpoints. Azure charges tiered egress: rates drop for higher volumes. First 100GB free.
A16: Region Group | B16: Volume (GB) | C16: Formula: Volume | D16: Tier1 $/GB ≤10TB | E16: Tier2 $/GB 10-50TB | F16: Tier3 $/GB 50-150TB | G16: Tier4 $/GB >150TB | H16: Egress Cost ($) | I16: Formula | J16: Notes
A17: US Regions — Non-Discovery sites only (EastUS2 + WestUS2 Safety Assessment, Microbial, RMS) | B17: =Assumptions!C18 -> 316261.82 | C17: Assumptions!C18 — US GiB × 1.074 | D17: =Assumptions!C31 -> 0.087 | E17: =Assumptions!C32 -> 0.083 | F17: =Assumptions!C33 -> 0.07 | G17: =Assumptions!C34 -> 0.05 | H17: =Assumptions!C31*MIN(Assumptions!C18,10240)+Assumptions!C32*MAX(0,MIN(Assumptions!C18-10240,40960))+Assumptions!C33*MAX(0,MIN(Assumptions!C18-51200,102400))+Assumptions!C34*MAX(0,Assumptions!C18-153600) -> 19591.651 | I17: Non-disc US egress only. Discovery EU data handled separately in Phase 2. | J17: Virginia→us-east-1, Washington→us-west-2
A18: EU Regions — Non-Discovery Safety Assessment only (EDI-SA, FRE-SA, EVR-SA, HER-SA) | B18: =Assumptions!C70 -> 27520.563 | C18: Assumptions!C70 — EU non-disc SA only (EDI+FRE+EVR+HER = 25,624 GiB × 1.074 = 27,520 GB) | D18: =Assumptions!C31 -> 0.087 | E18: =Assumptions!C32 -> 0.083 | F18: =Assumptions!C33 -> 0.07 | G18: =Assumptions!C34 -> 0.05 | H18: =Assumptions!C31*MIN(Assumptions!C70,10240)+Assumptions!C32*MAX(0,MIN(Assumptions!C70-10240,40960))+Assumptions!C33*MAX(0,MIN(Assumptions!C70-51200,102400))+Assumptions!C34*MAX(0,Assumptions!C70-153600) -> 2325.1667 | I18: EU non-disc SA sites only. Discovery EU sites (CRP/HAR/PTH/LEI/GRO/KUO/SZG) handled separately. | J18: UK→eu-west-2, NL→eu-west-1, DE→eu-central-1
A19: SUBTOTAL — AZURE EGRESS | H19: =SUM(H17:H18) -> 21916.818 | I19: SUM(H17:H18) — sum US+EU egress
A21: COMPONENT 3 — AWS S3 PUT REQUEST CHARGES (ingress to AWS is free; API calls are not)
A22: ℹ PUT rate varies by storage class. Glacier Deep Archive = $0.05/1K (10× Standard). Average file size is critical — adjust yellow cells. Object count = GiB×1024÷avg_MB.
A23: Storage Class | B23: Volume (GiB) | C23: Avg File MB ← INPUT | D23: Object Count | E23: Formula: Object Count | F23: PUT Rate ($/1K) | G23: Formula | H23: PUT Cost ($) | I23: Formula | J23: Notes
A24: S3 Standard (Std+Hot) | B24: =Assumptions!C6+Assumptions!C7 -> 4887.87 | C24: 10 | D24: =(B24*1024)/C24 -> 500517.89 | E24: (B24 gib × 1024 MB/GiB) ÷ C24 (avg MB per file)) | F24: =Assumptions!C46 -> 0.005 | G24: =Assumptions!C46 -> 0.005 | H24: =(D24/1000)*F24 -> 2.5025894 | I24: (object count ÷ 1000) × PUT rate) | J24: Low avg size — active files
A25: S3 Standard-IA (Cool) | B25: =Assumptions!C8 -> 14645.59 | C25: 50 | D25: =(B25*1024)/C25 -> 299941.68 | E25: (B25 gib × 1024 MB/GiB) ÷ C25 (avg MB per file)) | F25: =Assumptions!C47 -> 0.01 | G25: =Assumptions!C47 -> 0.01 | H25: =(D25/1000)*F25 -> 2.9994168 | I25: (object count ÷ 1000) × PUT rate) | J25: $0.01/1K — IA PUT rate higher
A26: S3 Glacier IR (Cold) | B26: =Assumptions!C9 -> 0 | C26: 200 | D26: =(B26*1024)/C26 -> 0 | E26: (B26 gib × 1024 MB/GiB) ÷ C26 (avg MB per file)) | F26: =Assumptions!C46 -> 0.005 | G26: =Assumptions!C46 -> 0.005 | H26: =(D26/1000)*F26 -> 0 | I26: (object count ÷ 1000) × PUT rate) | J26: Standard PUT rate
A27: S3 Glacier Deep Archive | B27: =Assumptions!C10 -> 300561.87 | C27: 500 | D27: =(B27*1024)/C27 -> 615550.71 | E27: (B27 gib × 1024 MB/GiB) ÷ C27 (avg MB per file)) | F27: =Assumptions!C48 -> 0.05 | G27: =Assumptions!C48 -> 0.05 | H27: =(D27/1000)*F27 -> 30.777535 | I27: (object count ÷ 1000) × PUT rate) | J27: ⚠ $0.05/1K — 10× Standard; file size critical
A28: SUBTOTAL — S3 PUT REQUESTS | H28: =SUM(H24:H27) -> 36.279542 | I28: SUM(H24:H27) — sum all PUT tiers
A30: COMPONENT 4 — POST-INGESTION LIFECYCLE TRANSITION CHARGES
A31: ℹ BEST PRACTICE: PUT directly into target storage class using --storage-class flag in DataSync. This makes transition cost $0. Option B shown for reference only.
A32: Option | B32: Target Class | C32: Object Count | D32: Formula | E32: Transition $/1K | F32: Formula | G32: Transition Cost ($) | H32: Formula | I32: Recommendation
A33: OPTION A (recommended): PUT directly to target class | B33: All classes | C33: =D24+D25+D26+D27 -> 1416010.3 | D33: Sum of all object counts from PUT section | E33: 0 | F33: 0 | G33: 0 | H33: 0 — PUT directly into target class: no lifecycle transition | I33: ✅ Use --storage-class flag per DataSync task. Zero cost.
A34: OPTION B: Land in Standard, transition to Standard-IA | B34: Standard-IA | C34: =D25 -> 299941.68 | D34: Cool object count from PUT section row D | E34: =Assumptions!C47 -> 0.01 | F34: =Assumptions!C47 -> 0.01 | G34: =(C34/1000)*E34 -> 2.9994168 | H34: (object count ÷ 1000) × transition rate) | I34: Avoid — use Option A above
A35: OPTION B: Land in Standard, transition to Deep Archive | B35: Glacier Deep Archive | C35: =D27 -> 615550.71 | D35: Archive object count from PUT section row D | E35: =Assumptions!C48 -> 0.05 | F35: =Assumptions!C48 -> 0.05 | G35: =(C35/1000)*E35 -> 30.777535 | H35: (object count ÷ 1000) × transition rate) | I35: ⚠ Most expensive — avoid for 882 TiB archive data
A38: COMPONENT 5 — AWS ONE-TIME SETUP & MIGRATION EXECUTION COSTS (complete HubStor replacement)
A39: Item | B39: Qty | C39: Formula: Qty | D39: Unit Cost ($) | E39: Formula | F39: Total Cost ($) | G39: Formula | H39: Notes
A40: AWS DataSync — data scanning/migration fee | B40: =320095.33*Assumptions!C11 -> 343782.38 | C40: Non-disc sites only (320,095 GiB × 1.074 = 343,782 GB) | D40: =Assumptions!C63 -> 0.0125 | E40: Assumptions!C63 ($0.0125/GB scanned) | F40: =B40*D40 -> 4297.2798 | G40: qty × Unit cost | H40: One-time migration tool — $0.0125/GB for all data scanned
A41: Storage Gateway VM setup & config (3 non-disc sites: US-East, US-West, EU-NL) | B41: =Assumptions!C54 -> 3 | C41: Assumptions!C54 (number of sites) | D41: 500 | E41: Estimated IT labor per site (internal cost) | F41: =B41*D41 -> 1500 | G41: qty × Unit cost | H41: Install Gateway VM, configure NFS/SMB shares, test connectivity
A42: S3 bucket creation, lifecycle policies, tagging | B42: 1 | C42: Fixed | D42: 500 | E42: One-time AWS console/CLI setup | F42: =B42*D42 -> 500 | G42: qty × Unit cost | H42: 5 buckets × 5 regions, lifecycle rules, Object Lock config
A43: IAM roles, policies, KMS key setup | B43: 1 | C43: Fixed | D43: 500 | E43: One-time security config | F43: =B43*D43 -> 500 | G43: qty × Unit cost | H43: Gateway IAM role, DataSync role, bucket policies, KMS CMKs
A44: Testing, validation & UAT | B44: 1 | C44: Fixed | D44: 3000 | E44: Internal resource time estimate | F44: =B44*D44 -> 3000 | G44: qty × Unit cost | H44: Data integrity checks, retrieval tests, connector smoke tests
A45: HubStor subscription decommission & contract mgmt | B45: 1 | C45: Fixed | D45: 2000 | E45: Legal/admin for contract termination | F45: =B45*D45 -> 2000 | G45: qty × Unit cost | H45: Notice period management, final data verification, sign-off
A46: SUBTOTAL — AWS SETUP COSTS | F46: =SUM(F40:F45) -> 11797.28 | G46: SUM(F40:F45) — sum all setup costs
...

Sheet Risks & Assumptions
A1: RISKS & ASSUMPTIONS — COMPLETE HUBSTOR + AZURE BLOB REPLACEMENT WITH AWS S3
A2: Must be reviewed and signed off before project commencement | Owner = Cloud Architecture Team
A4: KEY ASSUMPTIONS
A5: # | B5: Category | C5: Assumption | D5: Basis / Source | E5: If Wrong — Impact | F5: Owner | G5: Status
A6: A1 | B6: Pricing | C6: AWS list pricing held flat for 3-year model | D6: AWS published list rates March 2026 | E6: Costs could rise — actual savings may be lower | F6: Cloud Arch | G6: Confirmed
A7: A2 | B7: Pricing | C7: HubStor non-storage fee = 34.3% of storage cost (=$9,068÷$26,455) | D7: HubStor Master Report v5 actuals | E7: Ratio may vary monthly — directionally correct | F7: Finance | G7: Confirmed
A8: A3 | B8: Pricing | C8: Azure egress billed at public internet rates (not VPN) | D8: Architecture decision — direct to S3 public endpoint | E8: VPN routing adds AWS transit cost ($0.02/GB) — adds ~$18K | F8: Cloud Arch | G8: Decision required
A9: A4 | B9: Data | C9: All 1,041.7 TiB migrated to AWS (no data deleted pre-migration) | D9: HubStor Master Report v5 — all stors migrated | E9: Smaller dataset = lower migration cost; larger = higher | F9: Programme Mgr | G9: TBC
A10: A5 | B10: Data | C10: Archive avg file size = 500MB (PUT cost sensitivity) | D10: Assumed; actual could range 1MB-2GB (see sensitivity table) | E10: At 1MB avg: PUT cost rises by $45K; at 100MB: negligible | F10: Data Team | G10: Verify before migration
A11: A6 | B11: Data | C11: 5% annual data growth rate | D11: Conservative industry estimate for scientific archives | E11: Higher growth = higher AWS costs but also higher HubStor costs | F11: Data Team | G11: TBC
A12: A7 | B12: Architecture | C12: 5 Storage Gateway VMs required (1 per major site) | D12: Site topology from Connector Details sheet — MWN, WLM, RNO, UK, EU | E12: More sites = higher EC2/EBS cost; fewer = simpler but single-site risk | F12: Cloud Arch | G12: Review with sites
A13: A8 | B13: Architecture | C13: File Gateway (NFS/SMB) replaces all HubStor connectors | D13: HubStor connector list has 17+ connectors — all routed via Gateway | E13: Connector incompatibility = custom integration effort | F13: App Teams | G13: Verify each connector
A14: A9 | B14: Architecture | C14: Direct Connect NOT required — public internet sufficient | D14: Gateway uses HTTPS/TLS; adequate for archive workloads | E14: Bandwidth constraint at peak rehydration may slow retrieval | F14: Network Team | G14: Monitor in pilot
A15: A10 | B15: Migration | C15: Archive rehydration takes 15hr per batch (Azure Standard priority) | D15: Azure documentation — Standard priority SLA | E15: Expedited priority ($0.03/GB extra) available if timeline too slow | F15: Cloud Arch | G15: Plan buffer weeks 3-4
A16: A11 | B16: Migration | C16: DataSync used for US data; Rclone for EU (avoids AWS-specific tooling) | D16: Best practice for cross-cloud migration | E16: Tool failure = manual fallback; add 2-week buffer | F16: Migration Team | G16: TBC
... A21: A16 | B21: Commercial | C21: Wasabi not selected — AWS chosen for S3 API compatibility and GxP compliance | D21: Technical decision | E21: Wasabi at $6.99/TB = slightly cheaper; recalculate if Wasabi selected | F21: Cloud Arch | G21: Decision confirmed
A24: RISK REGISTER
A25: # | B25: Risk Description | C25: Likelihood | D25: Impact | E25: Risk Score | F25: Mitigation | G25: Residual Risk | H25: Owner
A26: R1 | B26: Archive rehydration bottleneck — 882 TiB of Archive data requires up to 15hr rehydration per batch. Migration could take 8-12 weeks for archive tier alone, causing HubStor overlap billing. | C26: HIGH | D26: HIGH | E26: 🔴 CRITICAL | F26: Start archive rehydration in Month 2 immediately. Run parallel batches. Budget for 2 months HubStor overlap (~$71K) in financial model. | G26: MEDIUM | H26: Cloud Arch
A27: R2 | B27: Azure egress cost overrun — Egress calculated at $64,645 but tiered pricing assumes linear volume. Actual rates depend on billing cycle timing. | C27: MEDIUM | D27: MEDIUM | E27: 🟡 MODERATE | F27: Negotiate Azure egress credits for large migration. Pre-announce to Azure account team. Consider doing migration over 2-3 billing cycles to stay in lower tiers. | G27: LOW | H27: Cloud Arch / Azure Rep
A28: R3 | B28: HubStor connector incompatibility — 17+ connectors across multiple sites may not work transparently with S3 File Gateway. DPI connectors (APO-PR-APP-*) may have custom metadata. | C28: MEDIUM | D28: HIGH | E28: 🔴 HIGH | F28: Pilot one connector type per site in Month 2 before full migration. Test DPI connectors specifically. Have HubStor support on standby. | G28: MEDIUM | H28: App Teams / HubStor
A29: R4 | B29: Data integrity loss during migration — File corruption or missing objects during Azure→S3 transfer. | C29: LOW | D29: CRITICAL | E29: 🟡 MODERATE | F29: MD5/ETag checksums validated by DataSync. Run post-migration inventory compare (S3 Inventory vs HubStor report). Do NOT decommission HubStor until 100% verified. | G29: LOW | H29: Migration Team
A30: R5 | B30: AWS Storage Gateway performance under load — Local cache (1TB EBS) may be insufficient for sites with high concurrent archive read requests. | C30: MEDIUM | D30: MEDIUM | E30: 🟡 MODERATE | F30: Monitor cache hit ratio from day 1. Increase EBS cache to 2TB if hit ratio <80%. Pre-warm cache for frequently accessed data. | G30: LOW | H30: Cloud Arch
A31: R6 | B31: Object Lock misconfiguration on GxP data — Incorrect retention period (too short or wrong mode) creates compliance gap. | C31: LOW | D31: CRITICAL | E31: 🟡 MODERATE | F31: Legal/QA review of retention periods before bucket creation. Use Compliance mode (not Governance). Test with non-regulated data first. | G31: LOW | H31: QA/Regulatory/Legal
A32: R7 | B32: Cost model underestimation — AWS S3 Glacier Deep Archive retrieval fees may be higher than estimated if archive access is more frequent than 0.5%/month. | C32: MEDIUM | D32: MEDIUM | E32: 🟡 MODERATE | F32: Monitor S3 retrieval metrics in CloudWatch from Month 1. Set Cost Anomaly Detection alerts at 120% of budget. Review quarterly. | G32: LOW | H32: Cloud Arch / Finance
A33: R8 | B33: HubStor contract lock-in — Contract may require >30 day notice or have early termination penalties. | C33: MEDIUM | D33: HIGH | E33: 🔴 HIGH | F33: Review HubStor contract IMMEDIATELY. If >30 day notice required, adjust timeline. Factor any penalties into migration cost. | G33: MEDIUM | H33: Legal / Finance
A34: R9 | B34: EU data sovereignty breach — Data temporarily routed outside correct region during migration. | C34: LOW | D34: CRITICAL | E34: 🟡 MODERATE | F34: Enforce bucket region from day 1 with SCP (Service Control Policy). No cross-region replication. Use AWS Config rule to alert on region violations. | G34: LOW | H34: Cloud Arch / Legal
A35: R10 | B35: Bandwidth saturation during migration — Simultaneous rehydration + egress from Azure may saturate site/DC internet links. | C35: MEDIUM | D35: MEDIUM | E35: 🟡 MODERATE | F35: Schedule migration transfers outside business hours. Set bandwidth limits in DataSync/Rclone. Start with smallest stor (RMS 914 GiB) as controlled pilot. | G35: LOW | H35: Network Team

Sheet 6-Month Migration Plan
A1: 6-MONTH MIGRATION PLAN — COMPLETE HUBSTOR → AWS S3 REPLACEMENT
A2: Phased approach: Pilot → US Regions → EU Regions → Cutover | Data residency preserved throughout | HubStor runs in parallel until Month 6
A4: PHASE OVERVIEW — TIMELINE AT A GLANCE
A5: Phase | B5: Description | C5: Month 1 | D5: Month 2 | E5: Month 3 | F5: Month 4 | G5: Month 5 | H5: Month 6 | I5: Key Milestone | J5: Owner | K5: Budget Impact ($) | L5: Status
A6: Phase 0 | B6: Foundation & Procurement | C6: ██████ | I6: AWS accounts active, IAM ready, HubStor contract notice served | J6: Cloud Arch | K6: =SUM(F41:F43) -> 0 | L6: Not started
A7: Phase 1 | B7: Pilot Migration (RMS East US) | D7: ██████ | I7: RMS 914 GiB migrated; Gateway tested; data integrity verified | J7: Migration Team | K7: ~$500 AWS costs only | L7: Not started
A8: Phase 2 | B8: US Regions (EastUS2 + WestUS2) | E8: ██████ | I8: 294 TiB US data migrated; US sites cut over to S3 Gateway | J8: Migration Team | K8: =H17*0.27 -> 0 | L8: Not started
A9: Phase 3 | B9: EU UK Region (UKSouth) | F9: ██████ | I9: 374 TiB UK data migrated; UK sites cut over | J9: Migration Team | K9: =H17*0.35 -> 0 | L9: Not started
A10: Phase 4 | B10: EU Continent (WestEurope + Germany) | G10: ██████ | I10: 398 TiB EU/DE data migrated; all EU sites cut over | J10: Migration Team | K10: =H17*0.38 -> 0 | L10: Not started
A11: Phase 5 | B11: Cutover, Decommission & Optimisation | H11: ██████ | I11: HubStor subscription cancelled; zero Azure Blob spend | J11: Cloud Arch / Finance | K11: First full month saving realised | L11: Not started
A13: PHASE 0 — FOUNDATION & PROCUREMENT (Month 1: Weeks 1-4)
A14: Week | B14: Category | C14: Task | D14: Owner | E14: Detail / Notes | F14: Success Criteria
A15: Week 1 | B15: Commercial | C15: Review and serve HubStor contract termination notice (verify notice period) | D15: Legal / Finance | E15: Notice period clock starts. If >30 days, adjust plan. | F15: CONTRACT NOTICE SERVED
A16: Week 1 | B16: AWS Setup | C16: Create AWS accounts per region (us-east-1, us-west-2, eu-west-2, eu-west-1, eu-central-1) | D16: Cloud Arch | E16: 5 AWS accounts or 1 org with SCPs per region | F16: Accounts active
A17: Week 1 | B17: AWS Setup | C17: Configure IAM: DataSync role, Gateway role, S3 bucket policies, KMS CMKs (1 per region) | D17: Cloud Arch | E17: All permissions least-privilege; tested with CLI | F17: IAM complete
A18: Week 2 | B18: AWS Setup | C18: Create S3 buckets with naming convention, Object Lock (Compliance mode), versioning policy | D18: Cloud Arch | E18: Bucket policy blocks public access; Object Lock enabled on GxP buckets | F18: Buckets created
A19: Week 2 | B19: AWS Setup | C19: Configure S3 lifecycle rules: Archive→Glacier Deep Archive on upload; Cool→Standard-IA | D19: Cloud Arch | E19: Lifecycle rules prevent objects landing in wrong tier | F19: Rules active
A20: Week 2 | B20: Monitoring | C20: Deploy CloudWatch dashboards: cost, storage usage, Gateway health, DataSync job status | D20: Cloud Arch | E20: Alerts configured for 120% budget threshold | F20: Dashboards live
A21: Week 3 | B21: Network | C21: Gateway VM deployment — install on-prem at WLM (pilot site). Configure NFS/SMB share | D21: Network + Cloud | E21: VM: m5.xlarge compatible VM on-prem. Attach 1TB EBS cache. Test HTTPS to S3. | F21: WLM Gateway online
A22: Week 3 | B22: Network | C22: Configure AWS VPC Gateway Endpoint for S3 (free — eliminates NAT Gateway fees if EC2 used) | D22: Cloud Arch | E22: Endpoint policy restricts access to specific buckets | F22: VPC endpoint active
A23: Week 4 | B23: Testing | C23: End-to-end connectivity test: write test file via Gateway → verify in S3 bucket → retrieve | D23: Migration Team | E23: Checksum match confirms data integrity path | F23: E2E test PASSED
A24: Week 4 | B24: Documentation | C24: Finalise migration runbook per site. DataSync job scripts prepared. Rollback plan documented | D24: Migration Team | E24: Runbook peer-reviewed | F24: Runbook signed off
A27: PHASE 1 — PILOT MIGRATION: RMS EAST US FILES (Month 2: ~914 GiB)
A28: Week | B28: Category | C28: Task | D28: Owner | E28: Detail / Notes | F28: Success Criteria
A29: Week 5 | B29: Migration | C29: Configure AWS DataSync: source=WLM-PR-FIL-05 Azure Blob, dest=S3 us-east-1 bucket | D29: Migration Team | E29: 3 DataSync tasks (3 connectors); --storage-class=STANDARD_IA for RMS data | F29: DataSync jobs configured
A30: Week 5 | B30: Migration | C30: Start DataSync transfer. Monitor CloudWatch for transfer rate, errors, throughput | D30: Migration Team | E30: Expected: ~200GB/hr → 914 GiB ≈ 5 hours. Run overnight. | F30: Transfer started
A31: Week 6 | B31: Validation | C31: Post-transfer: S3 Inventory report vs HubStor export — compare object counts and sizes | D31: Migration Team | E31: 100% object count match required before proceeding | F31: Integrity VERIFIED
A32: Week 6 | B32: Validation | C32: Retrieval test: retrieve 5 random files via S3 Gateway share. Verify content matches | D32: App Teams | E32: All 5 files open correctly; no corruption | F32: Retrieval PASSED
A33: Week 6 | B33: Cutover | C33: Update WLM-RMS connector to point to S3 File Gateway NFS share (change target path only) | D33: App Teams / Network | E33: Connector writes to S3 from this point; reads via Gateway cache | F33: Connector switched
A34: Week 7 | B34: Monitoring | C34: Monitor RMS connector for 1 week: write speed, retrieval latency, error rate | D34: Cloud Arch | E34: Target: <5s for cached reads; <30min for uncached archive fetch | F34: 1-week soak PASS
A35: Week 8 | B35: Review | C35: Pilot retrospective: document lessons, adjust runbook, confirm Phase 2 go/no-go | D35: Programme Mgr | E35: Signed go/no-go decision gate | F35: GO/NO-GO DECISION
A38: PHASE 2 — US REGIONS: EastUS2 + WestUS2 (Month 3: ~294 TiB)
A39: Week | B39: Category | C39: Task | D39: Owner | E39: Detail / Notes | F39: Success Criteria
A40: Week 9 | B40: Migration | C40: Begin archive rehydration for Safety Assessment East US (119 TiB archive). Submit rehydration job. | D40: Migration Team | E40: Azure Standard rehydration = up to 15hr. Batch by stor group. | F40: Rehydration started
A41: Week 9 | B41: Migration | C41: Deploy Gateway VM at MWN site (Safety Assessment). Configure connectors. | D41: Cloud Arch | E41: Mirror WLM setup. Same EBS cache size. Test connectivity. | F41: MWN Gateway ready
A42: Week 9 | B42: Migration | C42: Deploy Gateway VM at RNO site (Safety Assessment West). Configure connectors. | D42: Cloud Arch | E42: RNO covers WestUS2 data. | F42: RNO Gateway ready
A43: Week 10 | B43: Migration | C43: Start DataSync jobs: Microbial East US (25 TiB), RMS sub-stores remaining | D43: Migration Team | E43: Run overnight. Monitor DataSync CloudWatch dashboard. | F43: Microbial migrated
A44: Week 10 | B44: Migration | C44: Start DataSync jobs: Safety Assessment East US (after rehydration completes) | D44: Migration Team | E44: 122 TiB total. Largest US store. May take 2-3 nights. | F44: SA East migrated
A45: Week 11 | B45: Migration | C45: Start DataSync jobs: Safety Assessment West US (72 TiB WestUS2 data) | D45: Migration Team | E45: RNO connector data. Run over 2 nights. | F45: SA West migrated
A46: Week 11 | B46: Validation | C46: S3 Inventory cross-check for all US stores. Fix any gaps. | D46: Migration Team | E46: Zero discrepancy required | F46: US inventory matched
...

Sheet Financial Model (Jun26-Dec30)
A1: FINANCIAL MODEL — Jul 2026 to Dec 2030 | 3 Phases: Non-Disc Migration → Discovery Hand-Off → AWS Only
A2: Phase 1 (Jul–Dec 2026): Non-Discovery sites → AWS S3 via Storage Gateway | Phase 2 (Jan–Jun 2027): Discovery sites handed off to new company (CRL pays Azure extraction) | Phase 3 (Jul 2027–Dec 2030): AWS S3 only — full saving realised
A4: MODEL INPUTS
A5: HubStor monthly cost — NON-DISCOVERY sites only | B5: =Assumptions!C65 -> 10716.34 | C5: Safety Assessment (US/UK/EU) + Microbial + RMS = $10,716/mo
A6: HubStor monthly cost — DISCOVERY sites (Jan-Jun 2027 hand-off) | B6: =Assumptions!C66 -> 24806.78 | C6: FRI/CRP/HAR/PTH/LEI/GRO/KUO/SZG = $24,807/mo; reduces to $0 by Jul 2027
A7: FULL current baseline — ALL HubStor + Backup/DataBox (non-disc $10,716 + disc $24,807 + backup $3,000) | B7: =Assumptions!C65+Assumptions!C66+Assumptions!C67 -> 38523.12 | C7: Non-disc HubStor $10,716 + Discovery HubStor $24,807 + Backup $3,000 = $38,523/mo. Baseline for all saving calculations.
A8: AWS Total monthly (non-disc S3 + 3 Gateway appliances) | B8: ='Cost Comparison'!B39 -> 2291.1038 | C8: S3 storage $645 + 3 gateways $1,410 + ops $236 = $2,291/mo
A9: Phase 1 non-disc migration cost (total) | B9: ='Migration Plan & Costs'!C60 -> 45110.281 | C9: Azure retrieval+egress+DataSync+setup for non-disc sites only = $51,203
A10: Phase 2 discovery hand-off cost (total — our Azure extraction share) | B10: =SUM(F30:F35) -> 86843 | C10: Azure retrieval+egress+DataSync for 8 discovery site groups = $86,843
A11: Annual data growth rate | B11: =Assumptions!C64 -> 0.05 | C11: Applied from 2028 onwards
A12: Full steady-state monthly saving (Jul 2027+) | B12: =B7-B8 -> 36232.016 | C12: $38,523 full baseline - $2,291 AWS = $36,232/mo saving. Realised from Jul 2027 when all HubStor+Azure = $0.
A13: Payback — months from Jul 2027 (after all migration complete) | B13: =(SUM(F18:F23)+SUM(D18:D23)+SUM(F30:F35))/B12 -> 4.1540283 | C13: ~4.1 months from Jul 2027 | Phase1 mig $51,203 + Phase1 AWS overlap $11,363 + Phase2 disc $86,843 = $149,409 total investment
A15: PHASE 1 — NON-DISCOVERY MIGRATION TO AWS S3 (Jul 1 – Dec 31, 2026) | Safety Assessment, Microbial & RMS sites only | 3 Storage Gateway appliances
A16: DISCOVERY SITES (FRI/CRP/HAR/PTH/LEI/GRO/KUO/SZG) remain in Azure/HubStor throughout Phase 1 — they are NOT migrated to S3. AWS costs = 3 gateways + non-disc S3 storage only. HubStor cost steps down as non-disc Azure regions are deleted from Oct.
A17: # | B17: Calendar Month | C17: HubStor+Azure ($) [ALL sites — steps ↓ Oct+] | D17: AWS Cost ($) [non-disc ramp ↑] | E17: Total Monthly Spend (HubStor + AWS + Mig) | F17: Phase 1 Migration Cost ($) [non-disc data only] | G17: HubStor breakdown | H17: Monthly saving vs old $38,523 baseline | I17: Net Cumulative Saving ($) [negative = investment building]
A18: 1 | B18: Jul 2026 | C18: 38523.12 | D18: 835.02 | E18: =C18+D18+F18 -> 49598.8 | F18: 10240.66 | G18: All 5 regions (incl. Discovery) = $35,523 + $3,000 backup = $38,523 | H18: =38523.12-C18-D18 -> -835.02 | I18: =-SUM(D18:D18)-SUM(F18:F18) -> -11075.68
A19: 2 | B19: Aug 2026 | C19: 38523.12 | D19: 1498.55 | E19: =C19+D19+F19 -> 47014.67 | F19: 6993 | G19: All 5 regions = $35,523 + $3,000 backup = $38,523 | H19: =38523.12-C19-D19 -> -1498.55 | I19: =-SUM(D18:D19)-SUM(F18:F19) -> -19567.23
A20: 3 | B20: Sep 2026 | C20: 38523.12 | D20: 2194.34 | E20: =C20+D20+F20 -> 52005.79 | F20: 11288.33 | G20: All 5 regions = $35,523 + $3,000 backup = $38,523 | H20: =38523.12-C20-D20 -> -2194.34 | I20: =-SUM(D18:D20)-SUM(F18:F20) -> -33049.9
A21: 4 | B21: Oct 2026 | C21: 36314.79 | D21: 2258.85 | E21: =C21+D21+F21 -> 48044.3 | F21: 9470.66 | G21: Non-disc WestUS2 deleted (−$2,208). Disc sites unchanged. $36,315 total. | H21: =38523.12-C21-D21 -> -50.52 | I21: =-SUM(D18:D21)-SUM(F18:F21) -> -44779.41
A22: 5 | B22: Nov 2026 | C22: 28633.49 | D22: 2284.65 | E22: =C22+D22+F22 -> 37612.54 | F22: 6694.4 | G22: Non-disc EastUS2 deleted (−$7,681). Disc sites unchanged. $28,634 total. | H22: =38523.12-C22-D22 -> 7604.98 | I22: =-SUM(D18:D22)-SUM(F18:F22) -> -53758.46
A23: 6 | B23: Dec 2026 | C23: 28806.78 | D23: 2291.1 | E23: =C23+D23+F23 -> 38714.14 | F23: 7616.26 | G23: EU SA non-disc deleted (−$827). Disc still $24,807. Notice $1K + backup $3K = $28,807. | H23: =38523.12-C23-D23 -> 7425.24 | I23: =-SUM(D18:D23)-SUM(F18:F23) -> -63665.82
A24: 6 mo | B24: NON-DISC MIGRATION TOTAL Jul–Dec 2026 | C24: =SUM(C18:C23) -> 209324.42 | D24: =SUM(D18:D23) -> 11362.51 | E24: =SUM(E18:E23) -> 272990.24 | F24: =SUM(F18:F23) -> 52303.31 | G24: Note: HubStor cost stays flat Jul-Sep (disc sites still running). Steps down Oct-Dec as non-disc regions deleted. | H24: =SUM(H18:H23) -> 10451.79 | I24: =I23 -> -63665.82
A25: ✅ By Dec 2026: All non-discovery data is on AWS S3. All non-discovery Azure regions deleted. Discovery data still in Azure (HubStor $24,807/mo + backup $3,000 continuing). Phase 2 begins Jan 2027: hand off discovery sites to new company.
A27: PHASE 2 — DISCOVERY SITE HAND-OFF TO NEW COMPANY (Jan 2027 – Jun 2027) | Azure+HubStor cost steps DOWN as each site is transferred | CRL pays Azure extraction cost per site | AWS stays flat at $2,291/mo
A28: Each month one or more discovery site groups are extracted from Azure and handed to the new company. HubStor+Azure cost drops immediately when a site is transferred. CRL bears: Azure retrieval fees + Azure egress fees + DataSync fees per site (shown in column F). Net Cumulative Saving = savings vs doing nothing, minus ALL extra costs (AWS overlap + Phase 1 mig + Phase 2 mig).
A29: # | B29: Calendar Month | C29: HubStor + Azure ($) [steps ↓ each month] | D29: AWS S3 Cost ($) [flat $2,291/mo] | E29: Total Monthly Spend (HubStor + AWS + Mig) | F29: Discovery Mig Cost ($) [our Azure extraction] | G29: Sites transferred to new company & HubStor cost unlocked | H29: Monthly saving vs old $38,523 baseline | I29: Net Cumulative Saving ($) [vs doing nothing]
A30: 7 | B30: Jan 2027 | C30: 16743.52 | D30: =B8 -> 2291.1038 | E30: =C30+D30+F30 -> 55722.624 | F30: 36688 | G30: CRP-EarlyDiscovery (325,872 GiB) −$11,063/mo HubStor unlocked | H30: =38523.12-C30-D30 -> 19488.496 | I30: =I24+H30-F30 -> -80865.324
A31: 8 | B31: Feb 2027 | C31: 7594.2 | D31: =B8 -> 2291.1038 | E31: =C31+D31+F31 -> 42653.304 | F31: 32768 | G31: LEI-EarlyDiscovery (286,607 GiB) −$9,149/mo HubStor unlocked | H31: =38523.12-C31-D31 -> 28637.816 | I31: =I30+H31-F31 -> -84995.508
A32: 9 | B32: Mar 2027 | C32: 4658.17 | D32: =B8 -> 2291.1038 | E32: =C32+D32+F32 -> 17793.274 | F32: 10844 | G32: KUO-Discovery (34,060 GiB) + FRI-Discovery (48,444 GiB) −$2,936/mo HubStor unlocked | H32: =38523.12-C32-D32 -> 31573.846 | I32: =I31+H32-F32 -> -64265.661
A33: 10 | B33: Apr 2027 | C33: 3125.3 | D33: =B8 -> 2291.1038 | E33: =C33+D33+F33 -> 11444.404 | F33: 6028 | G33: PTH-Discovery (30,378 GiB) + HAR-EarlyDiscovery (17,264 GiB) −$1,533/mo HubStor unlocked | H33: =38523.12-C33-D33 -> 33106.716 | I33: =I32+H33-F33 -> -37186.945
A34: 11 | B34: May 2027 | C34: 3000 | D34: =B8 -> 2291.1038 | E34: =C34+D34+F34 -> 5806.1038 | F34: 515 | G34: GRO-Discovery (3,950 GiB) + SZG-Discovery (34 GiB) −$125/mo HubStor unlocked ✅ All discovery sites done | H34: =38523.12-C34-D34 -> 33232.016 | I34: =I33+H34-F34 -> -4469.9288
A35: 12 | B35: Jun 2027 | C35: 3000 | D35: =B8 -> 2291.1038 | E35: =C35+D35+F35 -> 5291.1038 | F35: 0 | G35: All discovery sites fully transferred to new company Backup/DataBox $3,000 ceasing — final month | H35: =38523.12-C35-D35 -> 33232.016 | I35: =I34+H35-F35 -> 28762.087
A36: 6 mo | B36: DISCOVERY HAND-OFF TOTAL Jan–Jun 2027 | C36: =SUM(C30:C35) -> 38121.19 | D36: =SUM(D30:D35) -> 13746.623 | E36: =SUM(E30:E35) -> 138710.81 | F36: =SUM(F30:F35) -> 86843 | G36: ✅ Jun 2027: All discovery handed off. Jul 2027+: HubStor=$0, Backup=$0, full $36,232/mo saving. | H36: =SUM(H30:H35) -> 179270.91 | I36: =I35 -> 28762.087
A38: PHASE 3 — AWS S3 ONLY (Jul 2027 – Dec 2030) | HubStor=$0 | Azure=$0 | Backup=$0 | Full $36,232/mo saving
A39: All HubStor and Azure costs are $0. AWS S3 stores non-discovery data only (320,095 GiB). Monthly saving = $38,523 (old full baseline) − $2,291 (AWS) = $36,232/mo. AWS cost grows 5% per year from 2028 as non-disc data volumes increase.
A40: # | B40: Calendar Month | C40: HubStor+Azure ($) | D40: AWS Total ($) | E40: Monthly Saving ($) [vs old $38,523] | F40: Cumul. Saving (from Jul 2027) | G40: — | H40: Monthly saving vs old baseline | I40: Net Cumulative Saving ($)
A41: 13 | B41: Jul 2027 | C41: 0 | D41: =B8 -> 2291.1038 | E41: =38523.12-D41 -> 36232.016 | F41: =SUM($E$41:E41) -> 36232.016 | G41: 0 | H41: =H36+E41 -> 215502.92 | I41: =I36+E41 -> 64994.104
A42: 14 | B42: Aug 2027 | C42: 0 | D42: =B8 -> 2291.1038 | E42: =38523.12-D42 -> 36232.016 | F42: =SUM($E$41:E42) -> 72464.032 | G42: 0 | H42: =H41+E42 -> 251734.94 | I42: =I41+E42 -> 101226.12
A43: 15 | B43: Sep 2027 | C43: 0 | D43: =B8 -> 2291.1038 | E43: =38523.12-D43 -> 36232.016 | F43: =SUM($E$41:E43) -> 108696.05 | G43: 0 | H43: =H42+E43 -> 287966.96 | I43: =I42+E43 -> 137458.14
A44: 16 | B44: Oct 2027 | C44: 0 | D44: =B8 -> 2291.1038 | E44: =38523.12-D44 -> 36232.016 | F44: =SUM($E$41:E44) -> 144928.06 | G44: 0 | H44: =H43+E44 -> 324198.97 | I44: =I43+E44 -> 173690.15
...

Sheet Architecture & Connectivity
A1: AWS S3 TARGET ARCHITECTURE — CONNECTIVITY & ACCESS DESIGN
A2: Full HubStor replacement | S3 File Gateway replaces all HubStor connectors | Data residency preserved per region
A4: STORAGE GATEWAY — HOW SITES CONNECT TO S3 (replaces HubStor connector agents)
A5: Pattern | B5: AWS S3 File Gateway (NFS/SMB shares) → replaces every HubStor connector agent at each site. S3-compatible. No application changes needed.
A6: What it is | B6: A VM (VMware / Hyper-V / KVM) deployed on-prem at each site. Presents NFS or SMB shares to local applications. Data written to shares is automatically uploaded to S3 as objects with compression and encryption.
A7: Archiving flow | B7: Application saves file → File Gateway share → Gateway caches locally → Compresses & uploads to S3 bucket (correct storage class via lifecycle rule) → File stays accessible via share (cached read).
A8: Retrieval flow | B8: User requests file from Gateway share → Gateway checks local 1TB EBS cache → If cached: instant return → If not cached: fetches from S3 (Standard-IA: ms; Glacier IR: ms; Deep Archive: restore first ~12-48hr) → Returns file.
A9: Sites & VMs | B9: 5 Gateway VMs required: • WLM (EastUS2) → us-east-1 • RNO (WestUS2) → us-west-2 • UK sites (UKSouth) → eu-west-2 • NL/EU sites (WestEurope) → eu-west-1 • DE site (GermanyWestCentral) → eu-central-1
A10: HubStor connectors replaced | B10: All 17+ DPI connectors (APO-PR-APP-*), NAS connectors (MWN-PR-FIL-01, WLM-PR-FIL-05), and test connectors replaced by gateway shares. One Gateway per site serves all connectors at that site.
A11: Migration tool | B11: AWS DataSync for bulk one-time migration (Azure Blob → S3). DataSync handles checksums, retry, parallelism. Post-migration: Gateway handles all incremental writes; DataSync not needed.
A13: S3 BUCKET STRATEGY
A14: Bucket per region (5 buckets) | B14: us-east-1: company-archive-us-east / us-west-2: company-archive-us-west / eu-west-2: company-archive-uk / eu-west-1: company-archive-eu / eu-central-1: company-archive-de
A15: Prefix / key structure | B15: s3://company-archive-{region}/{site-code}/{stor-name}/{year}/{month}/{filename} e.g., s3://company-archive-uk/CRP/EarlyDiscovery/2024/03/sample.raw
A16: Storage class mapping | B16: Standard/Hot → S3 Standard | Cool → S3 Standard-IA (lifecycle Day 0) | Cold → S3 Glacier Instant Retrieval | Archive → S3 Glacier Deep Archive (PUT directly via --storage-class)
A17: Lifecycle rules | B17: Lifecycle rule 1: Objects with tag tier=cool → Standard-IA immediately. Rule 2: Objects with tag tier=archive → Glacier Deep Archive immediately. Rule 3: Incomplete multipart uploads → abort after 7 days.
A18: Object Lock (GxP data) | B18: Enable S3 Object Lock in Compliance mode on buckets holding GxP-regulated data (Safety Assessment, Microbial). Retention period = defined by QA/Regulatory team. Objects cannot be deleted or modified during retention.
A19: Versioning | B19: Enable ONLY on compliance/GxP buckets. Do NOT enable on pure archive buckets (versioning doubles storage cost for every overwrite).
A20: Encryption | B20: SSE-S3 (AES-256) at zero extra cost as baseline. Upgrade to SSE-KMS for GxP data requiring audit trail of key access. 1 KMS CMK per region = $5/month total.
A21: VPC Gateway Endpoint | B21: Deploy free S3 VPC Gateway Endpoint in each AWS region to route S3 traffic within AWS backbone — eliminates NAT Gateway data processing charges if any EC2-based processing is added later.
A23: CONNECTIVITY OPTIONS
A24: Option A — HTTPS/TLS (Recommended, chosen for this design) | B24: Gateway VM uploads to S3 public endpoint over port 443 (HTTPS). Data is encrypted in transit (TLS 1.2+). No additional cost. All current sites have reliable internet. This is the chosen architecture.
A25: Option B — AWS Site-to-Site VPN (optional add-on) | B25: ~$0.05/hr per VPN connection = $36/mo. Use if security policy requires private connectivity. Can be added after cutover. Transit cost ~$0.01/GB within AWS. NOT required for launch.
A26: Option C — AWS Direct Connect (optional premium) | B26: Dedicated 1Gbps circuit ~$200-500/mo port cost. Use only if bandwidth becomes a demonstrated bottleneck after 3 months on Option A. Overkill for archive workloads.
