Workbook

Sheet Assumptions
A1: CENTRAL ASSUMPTIONS — ALL INPUTS IN ONE PLACE
A2: Yellow = hardcoded inputs (change here) | All other sheets reference these cells | Black text = formula | Blue text = linked input
A4: STORAGE VOLUMES (from HubStor Master Report v5)
A5: Parameter | B5: Cell Ref | C5: Value | D5: Unit | E5: Source / Notes
A6: Standard tier GiB | B6: A6 | C6: 7775.51 | D6: GiB | E6: HubStor Master Report v5 actuals
A7: Hot tier GiB | B7: A7 | C7: 7401.73 | D7: GiB | E7: HubStor Master Report v5 actuals
A8: Cool tier GiB | B8: A8 | C8: 165555.92 | D8: GiB | E8: HubStor Master Report v5 actuals
A9: Cold tier GiB | B9: A9 | C9: 3195.69 | D9: GiB | E9: HubStor Master Report v5 actuals
A10: Archive tier GiB | B10: A10 | C10: 882775.79 | D10: GiB | E10: HubStor Master Report v5 actuals
A11: GiB → GB conversion factor | B11: A11 | C11: 1.074 | D11: × | E11: 1 GiB = 1.074 GB (decimal)
A12: GiB per TiB (divisor) | B12: A12 | C12: 1024 | D12: ÷ | E12: 1 TiB = 1024 GiB
A13: Total GiB (all tiers) | B13: A13 | C13: =C6+C7+C8+C9+C10 -> 1066704.6 | D13: GiB | E13: Sum of all five tiers
A14: Total TiB | B14: A14 | C14: =C13/C12 -> 1041.7038 | D14: TiB | E14: Total GiB ÷ 1,024
A15: Total GB (decimal) | B15: A15 | C15: =C13*C11 -> 1145640.8 | D15: GB | E15: Total GiB × 1.074 (for Azure/AWS pricing which uses decimal GB)
A16: US region GiB | B16: A16 | C16: =221472.95+72998.02 -> 294470.97 | D16: GiB | E16: EastUS2 + WestUS2 (from Master Report)
A17: EU region GiB | B17: A17 | C17: =374040.18+349749.29+48444.2 -> 772233.67 | D17: GiB | E17: UKSouth + WestEurope + GermanyWestCentral
A18: US region GB | B18: A18 | C18: =C16*C11 -> 316261.82 | D18: GB | E18: US GiB × 1.074
A19: EU region GB | B19: A19 | C19: =C17*C11 -> 829378.96 | D19: GB | E19: EU GiB × 1.074
A21: AZURE / HUBSTOR PRICING
A22: Parameter | B22: Cell Ref | C22: Value | D22: Unit | E22: Source / Notes
A23: Azure Standard/Hot $/GB/mo | B23: A23 | C23: 0.02 | D23: $/GB/mo | E23: Azure Blob Standard pricing (public)
A24: Azure Cool $/GB/mo | B24: A24 | C24: 0.015 | D24: $/GB/mo | E24: Azure Blob Cool tier
A25: Azure Cold $/GB/mo | B25: A25 | C25: 0.01 | D25: $/GB/mo | E25: Azure Blob Cold tier
A26: Azure Archive $/GB/mo | B26: A26 | C26: 0.002 | D26: $/GB/mo | E26: Azure Blob Archive tier
A27: HubStor mgmt fee % of storage | B27: A27 | C27: 0.3428 | D27: % | E27: Actual ratio: $9,068 non-storage ÷ $26,455 storage from Master Report
A28: Azure Cool retrieval $/GB | B28: A28 | C28: 0.01 | D28: $/GB | E28: Azure Blob Cool read charge
A29: Azure Cold retrieval $/GB | B29: A29 | C29: 0.03 | D29: $/GB | E29: Azure Blob Cold read charge
A30: Azure Archive rehydration $/GB | B30: A30 | C30: 0.022 | D30: $/GB | E30: Standard rehydration priority (~15hr wait)
A31: Azure egress tier1 $/GB | B31: A31 | C31: 0.087 | D31: $/GB | E31: 0–10 TB internet egress
A32: Azure egress tier2 $/GB | B32: A32 | C32: 0.083 | D32: $/GB | E32: 10–50 TB internet egress
A33: Azure egress tier3 $/GB | B33: A33 | C33: 0.07 | D33: $/GB | E33: 50–150 TB internet egress
A34: Azure egress tier4 $/GB | B34: A34 | C34: 0.05 | D34: $/GB | E34: >150 TB internet egress
A36: AWS PRICING
A37: Parameter | B37: Cell Ref | C37: Value | D37: Unit | E37: Source / Notes
A38: S3 Standard $/GB/mo (US) | B38: A38 | C38: 0.023 | D38: $/GB/mo | E38: AWS us-east-1 list price 2026
A39: S3 Standard $/GB/mo (EU) | B39: A39 | C39: 0.024 | D39: $/GB/mo | E39: AWS EU regions list price
A40: S3 Standard-IA $/GB/mo (US) | B40: A40 | C40: 0.0125 | D40: $/GB/mo | E40: AWS Standard-IA storage rate
A41: S3 Standard-IA $/GB/mo (EU) | B41: A41 | C41: 0.013 | D41: $/GB/mo | E41: AWS EU Standard-IA
A42: S3 Glacier IR $/GB/mo (US) | B42: A42 | C42: 0.004 | D42: $/GB/mo | E42: Glacier Instant Retrieval
A43: S3 Glacier IR $/GB/mo (EU) | B43: A43 | C43: 0.0045 | D43: $/GB/mo | E43: Glacier IR EU
...

Sheet Executive Summary
A1: HUBSTOR → AWS S3 COMPLETE MIGRATION | BUSINESS CASE & COST ANALYSIS
A2: Prepared for Internal Review | Based on HubStor Master Report v5 | Full HubStor + Azure Blob replacement
A4: CURRENT HUBSTOR + AZURE COST | D4: AWS TOTAL MONTHLY (after migration) | G4: MONTHLY SAVING (HubStor − AWS) | J4: ONE-TIME MIGRATION COST
A5: =Assumptions!C65 -> 35523.12 | D5: ='Cost Comparison'!B37 -> 6196.0458 | G5: =Assumptions!C65-'Cost Comparison'!B37 -> 29327.074 | J5: ='Migration Plan & Costs'!C60 -> 121370.23
A6: ="$"&TEXT(Assumptions!C65*12,"#,##0")&"/yr | 1,042 TiB | 5 Azure regions" -> $426,277/yr | 1,042 TiB | 5 Azure regions | D6: ="$"&TEXT('Cost Comparison'!B37*12,"#,##0")&"/yr | S3 storage + Gateway appliance" -> $74,353/yr | S3 storage + Gateway appliance | G6: ="$"&TEXT((Assumptions!C65-'Cost Comparison'!B37)*12,"#,##0")&"/yr saved | "&TEXT((Assumptions!C65-'Cost Comparison'!B37)/Assumptions!C65,"0%")&" cost reduction" -> $351,925/yr saved | 83% cost reduction | J6: ="Payback: ~"&TEXT(('Migration Plan & Costs'!B60+'Financial Model (Jun26-Dec30)'!B11)/(Assumptions!C65-'Cost Comparison'!B37),"0.0")&" months after migration (Jan 2027 + migration cost + Phase 1 AWS overlap)" -> Payback: ~5.0 months after migration (Jan 2027 + migration cost + Phase 1 AWS overlap)
A8: CURRENT HUBSTOR COSTS BY AZURE REGION (Source: HubStor Master Report v5)
A9: Azure Region | B9: Azure Location | C9: Total Usage (GiB) | D9: Formula: GiB | E9: Storage Cost/mo ($) | F9: Non-Storage/HubStor Fee ($) | G9: Total Cost/mo ($) | H9: Formula: Total
A10: EastUS2 | B10: Virginia, USA | C10: 221472.95 | D10: Hardcoded from Master Report | E10: 5798.59 | F10: 1882.71 | G10: =E10+F10 -> 7681.3 | H10: Storage + HubStor platform/non-storage fee
A11: GermanyWestCentral | B11: Frankfurt, Germany | C11: 48444.2 | D11: Hardcoded from Master Report | E11: 1337.27 | F11: 411.82 | G11: =E11+F11 -> 1749.09 | H11: Storage + HubStor platform/non-storage fee
A12: UKSouth | B12: London, UK | C12: 374040.18 | D12: Hardcoded from Master Report | E12: 9432.17 | F12: 3179.68 | G12: =E12+F12 -> 12611.85 | H12: Storage + HubStor platform/non-storage fee
A13: WestEurope | B13: Amsterdam, Netherlands | C13: 349749.29 | D13: Hardcoded from Master Report | E13: 8299.36 | F13: 2973.19 | G13: =E13+F13 -> 11272.55 | H13: Storage + HubStor platform/non-storage fee
A14: WestUS2 | B14: Washington, USA | C14: 72998.02 | D14: Hardcoded from Master Report | E14: 1587.78 | F14: 620.55 | G14: =E14+F14 -> 2208.33 | H14: Storage + HubStor platform/non-storage fee
A15: GRAND TOTAL | B15: All 5 Azure Regions | C15: =SUM(C10:C14) -> 1066704.6 | D15: SUM(C10:C14) — sum all regions | E15: =SUM(E10:E14) -> 26455.17 | F15: =SUM(F10:F14) -> 9067.95 | G15: =SUM(G10:G14) -> 35523.12 | H15: Storage Cost + Non-Storage/HubStor platform fee
A17: STORAGE BY AZURE TIER (all values from Assumptions sheet — change inputs there)
A18: Azure Tier | B18: Equiv. AWS Class | C18: Usage (GiB) | D18: Usage (TiB) | E18: % of Total | F18: Azure $/GB/mo
A19: Standard | B19: S3 Standard | C19: =Assumptions!C6 -> 7775.51 | D19: =C19/1024 -> 7.5932715 | E19: =C19/Assumptions!C13 -> 0.0072892811 | F19: =Assumptions!C23 -> 0.02
A20: Hot | B20: S3 Standard | C20: =Assumptions!C7 -> 7401.73 | D20: =C20/1024 -> 7.228252 | E20: =C20/Assumptions!C13 -> 0.0069388749 | F20: =Assumptions!C23 -> 0.02
A21: Cool | B21: S3 Standard-IA | C21: =Assumptions!C8 -> 165555.92 | D21: =C21/1024 -> 161.6757 | E21: =C21/Assumptions!C13 -> 0.15520315 | F21: =Assumptions!C24 -> 0.015
A22: Cold | B22: S3 Glacier IR | C22: =Assumptions!C9 -> 3195.69 | D22: =C22/1024 -> 3.120791 | E22: =C22/Assumptions!C13 -> 0.0029958527 | F22: =Assumptions!C25 -> 0.01
A23: Archive | B23: S3 Deep Archive | C23: =Assumptions!C10 -> 882775.79 | D23: =C23/1024 -> 862.08573 | E23: =C23/Assumptions!C13 -> 0.82757284 | F23: =Assumptions!C26 -> 0.002
A24: TOTAL | C24: =Assumptions!C13 -> 1066704.6 | D24: =C24/1024 -> 1041.7038 | E24: =SUM(E19:E23) -> 1

Sheet Cost Comparison
A1: AZURE HUBSTOR vs AWS S3 — COMPLETE COST COMPARISON (Storage + All Infrastructure)
A2: All values linked to Assumptions sheet | Black = formula | Blue = hardcoded input | Green = cross-sheet link | Yellow = input cell
A4: TIER PRICING ASSUMPTIONS (all rates from Assumptions sheet — edit there)
A5: Storage Tier | B5: Azure Tier | C5: Azure $/GB/mo | D5: Formula | E5: AWS Class | F5: AWS $/GB/mo (blended) | G5: Formula | H5: HubStor Mgmt % | I5: Formula | J5: Min Duration | K5: Notes
A6: Standard/Hot | B6: Standard/Hot | C6: =Assumptions!C23 -> 0.02 | D6: =Assumptions!C22 -> Value | E6: S3 Standard | F6: =(Assumptions!C38+Assumptions!C39)/2 -> 0.0235 | G6: (Assumptions!C36+Assumptions!C37)/2 — avg US+EU | H6: =Assumptions!C27 -> 0.3428 | I6: =Assumptions!C26 -> 0.002 | J6: None | K6: Active files; low % of total
A7: Cool | B7: Cool | C7: =Assumptions!C24 -> 0.015 | D7: =Assumptions!C23 -> 0.02 | E7: S3 Standard-IA | F7: =(Assumptions!C40+Assumptions!C41)/2 -> 0.01275 | G7: =(Assumptions!C38+Assumptions!C39)/2 -> 0.0235 | H7: =Assumptions!C27 -> 0.3428 | I7: =Assumptions!C26 -> 0.002 | J7: 30 days | K7: Retrieval fee applies
A8: Cold | B8: Cold | C8: =Assumptions!C25 -> 0.01 | D8: =Assumptions!C24 -> 0.015 | E8: S3 Glacier IR | F8: =(Assumptions!C42+Assumptions!C43)/2 -> 0.00425 | G8: =(Assumptions!C40+Assumptions!C41)/2 -> 0.01275 | H8: =Assumptions!C27 -> 0.3428 | I8: =Assumptions!C26 -> 0.002 | J8: 90 days | K8: Millisecond retrieval
A9: Archive | B9: Archive | C9: =Assumptions!C26 -> 0.002 | D9: =Assumptions!C25 -> 0.01 | E9: S3 Deep Archive | F9: =(Assumptions!C44+Assumptions!C45)/2 -> 0.000995 | G9: =(Assumptions!C42+Assumptions!C43)/2 -> 0.00425 | H9: =Assumptions!C27 -> 0.3428 | I9: =Assumptions!C26 -> 0.002 | J9: 180 days | K9: Dominant tier — 83% of data
A11: MONTHLY COST COMPARISON BY STORAGE TIER
A12: Tier | B12: Usage (GiB) | C12: Usage (TiB) | D12: Formula: TiB | E12: Azure Storage $/mo | F12: Formula | G12: HubStor Mgmt $/mo | H12: Formula | I12: Azure Total $/mo | J12: Formula | K12: AWS Storage $/mo | L12: Formula | M12: Monthly Saving $ | N12: Formula
A13: Standard/Hot | B13: =Assumptions!C6+Assumptions!C7 -> 15177.24 | C13: =B13/1024 -> 14.821523 | D13: B13÷1024 | E13: =B13*Assumptions!C11*Assumptions!C23 -> 326.00712 | F13: B13×Assumptions CC23×1.074 (GiB→GB×$/GB) | G13: =E13*Assumptions!C27 -> 111.75524 | H13: azure storage × HubStor mgmt% | I13: =E13+G13 -> 437.76235 | J13: azure storage + hubstor mgmt fee | K13: =B13*Assumptions!C11*(Assumptions!C38+Assumptions!C39)/2 -> 383.05836 | L13: B13×1.074×Blended Standard/Hot AWS price | M13: =I13-K13 -> 54.703994 | N13: Azure Total - AWS Storage = monthly saving
A14: Cool | B14: =Assumptions!C8 -> 165555.92 | C14: =B14/1024 -> 161.6757 | D14: B14÷1024 | E14: =B14*Assumptions!C11*Assumptions!C24 -> 2667.1059 | F14: B14×Assumptions CC24×1.074 (GiB→GB×$/GB) | G14: =E14*Assumptions!C27 -> 914.28389 | H14: azure storage × HubStor mgmt% | I14: =E14+G14 -> 3581.3898 | J14: azure storage + hubstor mgmt fee | K14: =B14*Assumptions!C11*(Assumptions!C40+Assumptions!C41)/2 -> 2267.04 | L14: B14×1.074×Standard-IA blended | M14: =I14-K14 -> 1314.3498 | N14: Azure Total - AWS Storage = monthly saving
A15: Cold | B15: =Assumptions!C9 -> 3195.69 | C15: =B15/1024 -> 3.120791 | D15: B15÷1024 | E15: =B15*Assumptions!C11*Assumptions!C25 -> 34.321711 | F15: B15×Assumptions CC25×1.074 (GiB→GB×$/GB) | G15: =E15*Assumptions!C27 -> 11.765482 | H15: azure storage × HubStor mgmt% | I15: =E15+G15 -> 46.087193 | J15: azure storage + hubstor mgmt fee | K15: =B15*Assumptions!C11*(Assumptions!C42+Assumptions!C43)/2 -> 14.586727 | L15: B15×1.074×Glacier IR blended | M15: =I15-K15 -> 31.500466 | N15: Azure Total - AWS Storage = monthly saving
A16: Archive | B16: =Assumptions!C10 -> 882775.79 | C16: =B16/1024 -> 862.08573 | D16: B16÷1024 | E16: =B16*Assumptions!C11*Assumptions!C26 -> 1896.2024 | F16: B16×Assumptions CC26×1.074 (GiB→GB×$/GB) | G16: =E16*Assumptions!C27 -> 650.01818 | H16: azure storage × HubStor mgmt% | I16: =E16+G16 -> 2546.2206 | J16: azure storage + hubstor mgmt fee | K16: =B16*Assumptions!C11*(Assumptions!C44+Assumptions!C45)/2 -> 943.36069 | L16: B16×1.074×Glacier Deep Archive blended | M16: =I16-K16 -> 1602.8599 | N16: Azure Total - AWS Storage = monthly saving
A17: STORAGE SUBTOTAL | B17: =SUM(B13:B16) -> 1066704.6 | C17: =SUM(C13:C16) -> 1041.7038 | E17: =SUM(E13:E16) -> 4923.6371 | G17: =SUM(G13:G16) -> 1687.8228 | I17: =SUM(I13:I16) -> 6611.4599 | K17: =SUM(K13:K16) -> 3608.0458 | M17: =SUM(M13:M16) -> 3003.4141
A19: AWS INFRASTRUCTURE COSTS — Storage Gateway Appliance Architecture (On-prem → Appliance → S3)
A20: Resource | B20: Qty | C20: Unit Cost /mo | D20: Monthly ($) | E20: Annual ($) | F20: Notes
A21: Storage Gateway Hardware Appliance (5 sites × amortised) | B21: =Assumptions!C54 -> 5 | C21: =Assumptions!C52 -> 470 | D21: =B21*C21 -> 2350 | E21: =D21*12 -> 28200 | F21: AWS-sold hardware appliance ~$16,920/unit ÷ 36mo = $470/site/mo. No EC2, no EBS needed.
A22: S3 Transfer Acceleration (optional — set $0 for archive) | B22: 1 | C22: =Assumptions!C53 -> 0 | D22: =B22*C22 -> 0 | E22: =D22*12 -> 0 | F22: Only needed if upload speed over long-distance WAN is critical. Archive workloads: $0.
A23: CloudWatch (monitoring, dashboards, alarms, logs) | B23: 1 | C23: =Assumptions!C55 -> 31 | D23: =B23*C23 -> 31 | E23: =D23*12 -> 372 | F23: Dashboards + custom metrics + CloudWatch alarms + log ingestion
A24: AWS KMS — Customer Managed Keys (1 per region × 5) | B24: =Assumptions!C57 -> 5 | C24: =Assumptions!C56 -> 1 | D24: =B24*C24 -> 5 | E24: =D24*12 -> 60 | F24: $1/key/mo × 5 regions = $5/mo. Encrypts S3 objects and Gateway cache.
A25: SNS — cost & health alert notifications | B25: 1 | C25: =Assumptions!C58 -> 2 | D25: =B25*C25 -> 2 | E25: =D25*12 -> 24 | F25: Alert topics for budget anomalies and Gateway connectivity issues
A26: AWS Config — compliance rule evaluation | B26: 1 | C26: =Assumptions!C59 -> 10 | D26: =B26*C26 -> 10 | E26: =D26*12 -> 120 | F26: GxP/regulatory config rules on S3 buckets. Object Lock compliance checks.
A27: S3 API Operations — ongoing PUTs/GETs (new archive writes) | B27: 1 | C27: =Assumptions!C60 -> 65 | D27: =B27*C27 -> 65 | E27: =D27*12 -> 780 | F27: Estimated monthly API cost for new data written from all 5 gateway sites
A28: Glacier Deep Archive retrieval fees (ongoing, est. 0.5%/mo) | B28: 1 | C28: =Assumptions!C61 -> 86 | D28: =B28*C28 -> 86 | E28: =D28*12 -> 1032 | F28: 0.5% of 862 TiB retrieved/mo × $0.02/GB restore fee
A29: S3 egress to internet (end-user retrieval, est.) | B29: 1 | C29: =Assumptions!C62 -> 39 | D29: =B29*C29 -> 39 | E29: =D29*12 -> 468 | F29: ~10% of retrieved data sent externally. Rest served within AWS/Gateway.
A30: INFRASTRUCTURE SUBTOTAL | D30: =SUM(D21:D29) -> 2588 | E30: =SUM(E21:E29) -> 31056
A32: TOTAL COST SUMMARY — HUBSTOR (CURRENT) vs AWS S3 COMPLETE REPLACEMENT
A33: Line Item | B33: Monthly ($) | C33: Annual ($) | D33: Saving vs HubStor | E33: % Reduction | F33: Notes
A34: Current HubStor + Azure Blob (ALL-IN) | B34: =Assumptions!C65 -> 35523.12 | C34: =Assumptions!C65*12 -> 426277.44 | D34: $0 | E34: 0% | F34: Actuals from Master Report
A35: AWS S3 Storage Cost (all 5 tiers) | B35: =K17 -> 3608.0458 | C35: =K17*12 -> 43296.549 | D35: =Assumptions!C65-K17 -> 31915.074 | E35: =(Assumptions!C65-K17)/Assumptions!C65 -> 0.89843106 | F35: Pure S3 storage — Standard/IA/GlacierIR/DeepArchive
A36: AWS Infrastructure (Gateway appliance + ops) | B36: =D30 -> 2588 | C36: =E30 -> 31056 | F36: Appliance amortisation, KMS, CloudWatch, API ops, egress
A37: AWS TOTAL (Storage + Infrastructure) | B37: =B35+B36 -> 6196.0458 | C37: =C35+C36 -> 74352.549 | D37: =B34-B37 -> 29327.074 | E37: =(B34-B37)/B34 -> 0.8255771 | F37: Complete like-for-like replacement of HubStor

Sheet Migration Plan & Costs
A1: ONE-TIME MIGRATION COSTS — COMPLETE ITEMIZED BREAKDOWN (All formulas shown)
A2: All four cost components + AWS setup costs | Black = formula | Blue/Yellow = input | Route: Azure → Public internet → S3 (NOT via VPN)
A4: COMPONENT 1 — AZURE RETRIEVAL CHARGES (reading data out of Azure Blob before egress)
A5: ℹ Standard/Hot: no retrieval fee. Cool=$0.01/GB. Cold=$0.03/GB. Archive=$0.022/GB (Standard rehydration, ~15hr wait — factor into timeline)
A6: Azure Tier | B6: GiB (input) | C6: GB (decimal) | D6: Formula: GB | E6: Retrieval $/GB | F6: Formula | G6: Retrieval Cost ($) | H6: Formula | I6: Notes
A7: Standard | B7: =Assumptions!C6 -> 7775.51 | C7: =B7*Assumptions!C11 -> 8350.8977 | D7: B7×Assumptions!C11 (GiB→GB) | E7: 0 | F7: 0 | G7: 0 | H7: No charge — Standard tier: read freely at no cost | I7: No retrieval fee
A8: Hot | B8: =Assumptions!C7 -> 7401.73 | C8: =B8*Assumptions!C11 -> 7949.458 | D8: B8×Assumptions!C11 (GiB→GB) | E8: 0 | F8: 0 | G8: 0 | H8: No charge — Hot tier: read freely at no cost | I8: No retrieval fee
A9: Cool | B9: =Assumptions!C8 -> 165555.92 | C9: =B9*Assumptions!C11 -> 177807.06 | D9: B9×Assumptions!C11 (GiB→GB) | E9: =Assumptions!C28 -> 0.01 | F9: =Assumptions!C28 -> 0.01 | G9: =C9*E9 -> 1778.0706 | H9: C9×E9 (GB × retrieval rate) | I9: Per-GB read charge
A10: Cold | B10: =Assumptions!C9 -> 3195.69 | C10: =B10*Assumptions!C11 -> 3432.1711 | D10: B10×Assumptions!C11 (GiB→GB) | E10: =Assumptions!C29 -> 0.03 | F10: =Assumptions!C29 -> 0.03 | G10: =C10*E10 -> 102.96513 | H10: C10×E10 (GB × retrieval rate) | I10: Per-GB read charge
A11: Archive | B11: =Assumptions!C10 -> 882775.79 | C11: =B11*Assumptions!C11 -> 948101.2 | D11: B11×Assumptions!C11 (GiB→GB) | E11: =Assumptions!C30 -> 0.022 | F11: =Assumptions!C30 -> 0.022 | G11: =C11*E11 -> 20858.226 | H11: C11×E11 (GB × retrieval rate) | I11: Standard rehydration rate (15hr per batch)
A12: SUBTOTAL — AZURE RETRIEVAL | G12: =SUM(G7:G11) -> 22739.262 | H12: SUM(G7:G11) — sum all five tiers
A14: COMPONENT 2 — AZURE EGRESS CHARGES (direct to S3 public endpoint — NOT via VPN)
A15: ℹ VPN routing adds AWS transit/inspection costs. Use S3 public endpoints. Azure charges tiered egress: rates drop for higher volumes. First 100GB free.
A16: Region Group | B16: Volume (GB) | C16: Formula: Volume | D16: Tier1 $/GB ≤10TB | E16: Tier2 $/GB 10-50TB | F16: Tier3 $/GB 50-150TB | G16: Tier4 $/GB >150TB | H16: Egress Cost ($) | I16: Formula | J16: Notes
A17: US Regions (EastUS2 + WestUS2) | B17: =Assumptions!C18 -> 316261.82 | C17: Assumptions!C18 — US GiB × 1.074 | D17: =Assumptions!C31 -> 0.087 | E17: =Assumptions!C32 -> 0.083 | F17: =Assumptions!C33 -> 0.07 | G17: =Assumptions!C34 -> 0.05 | H17: 19494.4 | I17: eastus2+westus2 gib×1.074 then tiered: 100GB free + 9900GB×$0.087 + 40000GB×$0.083 + 100000GB×$0.070 + remainder×$0.050 | J17: Virginia→us-east-1, Washington→us-west-2
A18: EU Regions (UKSouth + WestEurope + GermanyWestCentral) | B18: =Assumptions!C19 -> 829378.96 | C18: Assumptions!C19 — EU GiB × 1.074 | D18: =Assumptions!C31 -> 0.087 | E18: =Assumptions!C32 -> 0.083 | F18: =Assumptions!C33 -> 0.07 | G18: =Assumptions!C34 -> 0.05 | H18: 45150.25 | I18: eu gib×1.074 tiered: 100GB free + 9900GB×$0.087 + 40000GB×$0.083 + 100000GB×$0.070 + remainder×$0.050 | J18: UK→eu-west-2, NL→eu-west-1, DE→eu-central-1
A19: SUBTOTAL — AZURE EGRESS | H19: =SUM(H17:H18) -> 64644.65 | I19: SUM(H17:H18) — sum US+EU egress
A21: COMPONENT 3 — AWS S3 PUT REQUEST CHARGES (ingress to AWS is free; API calls are not)
A22: ℹ PUT rate varies by storage class. Glacier Deep Archive = $0.05/1K (10× Standard). Average file size is critical — adjust yellow cells. Object count = GiB×1024÷avg_MB.
A23: Storage Class | B23: Volume (GiB) | C23: Avg File MB ← INPUT | D23: Object Count | E23: Formula: Object Count | F23: PUT Rate ($/1K) | G23: Formula | H23: PUT Cost ($) | I23: Formula | J23: Notes
A24: S3 Standard (Std+Hot) | B24: =Assumptions!C6+Assumptions!C7 -> 15177.24 | C24: 10 | D24: =(B24*1024)/C24 -> 1554149.4 | E24: (B24 gib × 1024 MB/GiB) ÷ C24 (avg MB per file)) | F24: =Assumptions!C46 -> 0.005 | G24: =Assumptions!C46 -> 0.005 | H24: =(D24/1000)*F24 -> 7.7707469 | I24: (object count ÷ 1000) × PUT rate) | J24: Low avg size — active files
A25: S3 Standard-IA (Cool) | B25: =Assumptions!C8 -> 165555.92 | C25: 50 | D25: =(B25*1024)/C25 -> 3390585.2 | E25: (B25 gib × 1024 MB/GiB) ÷ C25 (avg MB per file)) | F25: =Assumptions!C47 -> 0.01 | G25: =Assumptions!C47 -> 0.01 | H25: =(D25/1000)*F25 -> 33.905852 | I25: (object count ÷ 1000) × PUT rate) | J25: $0.01/1K — IA PUT rate higher
A26: S3 Glacier IR (Cold) | B26: =Assumptions!C9 -> 3195.69 | C26: 200 | D26: =(B26*1024)/C26 -> 16361.933 | E26: (B26 gib × 1024 MB/GiB) ÷ C26 (avg MB per file)) | F26: =Assumptions!C46 -> 0.005 | G26: =Assumptions!C46 -> 0.005 | H26: =(D26/1000)*F26 -> 0.081809664 | I26: (object count ÷ 1000) × PUT rate) | J26: Standard PUT rate
A27: S3 Glacier Deep Archive | B27: =Assumptions!C10 -> 882775.79 | C27: 500 | D27: =(B27*1024)/C27 -> 1807924.8 | E27: (B27 gib × 1024 MB/GiB) ÷ C27 (avg MB per file)) | F27: =Assumptions!C48 -> 0.05 | G27: =Assumptions!C48 -> 0.05 | H27: =(D27/1000)*F27 -> 90.396241 | I27: (object count ÷ 1000) × PUT rate) | J27: ⚠ $0.05/1K — 10× Standard; file size critical
A28: SUBTOTAL — S3 PUT REQUESTS | H28: =SUM(H24:H27) -> 132.15465 | I28: SUM(H24:H27) — sum all PUT tiers
A30: COMPONENT 4 — POST-INGESTION LIFECYCLE TRANSITION CHARGES
A31: ℹ BEST PRACTICE: PUT directly into target storage class using --storage-class flag in DataSync. This makes transition cost $0. Option B shown for reference only.
A32: Option | B32: Target Class | C32: Object Count | D32: Formula | E32: Transition $/1K | F32: Formula | G32: Transition Cost ($) | H32: Formula | I32: Recommendation
A33: OPTION A (recommended): PUT directly to target class | B33: All classes | C33: =D24+D25+D26+D27 -> 6769021.4 | D33: Sum of all object counts from PUT section | E33: 0 | F33: 0 | G33: 0 | H33: 0 — PUT directly into target class: no lifecycle transition | I33: ✅ Use --storage-class flag per DataSync task. Zero cost.
A34: OPTION B: Land in Standard, transition to Standard-IA | B34: Standard-IA | C34: =D25 -> 3390585.2 | D34: Cool object count from PUT section row D | E34: =Assumptions!C47 -> 0.01 | F34: =Assumptions!C47 -> 0.01 | G34: =(C34/1000)*E34 -> 33.905852 | H34: (object count ÷ 1000) × transition rate) | I34: Avoid — use Option A above
A35: OPTION B: Land in Standard, transition to Deep Archive | B35: Glacier Deep Archive | C35: =D27 -> 1807924.8 | D35: Archive object count from PUT section row D | E35: =Assumptions!C48 -> 0.05 | F35: =Assumptions!C48 -> 0.05 | G35: =(C35/1000)*E35 -> 90.396241 | H35: (object count ÷ 1000) × transition rate) | I35: ⚠ Most expensive — avoid for 882 TiB archive data
A38: COMPONENT 5 — AWS ONE-TIME SETUP & MIGRATION EXECUTION COSTS (complete HubStor replacement)
A39: Item | B39: Qty | C39: Formula: Qty | D39: Unit Cost ($) | E39: Formula | F39: Total Cost ($) | G39: Formula | H39: Notes
A40: AWS DataSync — data scanning/migration fee | B40: =Assumptions!C15 -> 1145640.8 | C40: Assumptions!C15 (total GB decimal) | D40: =Assumptions!C63 -> 0.0125 | E40: Assumptions!C63 ($0.0125/GB scanned) | F40: =B40*D40 -> 14320.51 | G40: qty × Unit cost | H40: One-time migration tool — $0.0125/GB for all data scanned
A41: Storage Gateway VM setup & config (5 sites) | B41: =Assumptions!C54 -> 5 | C41: Assumptions!C54 (number of sites) | D41: 500 | E41: Estimated IT labor per site (internal cost) | F41: =B41*D41 -> 2500 | G41: qty × Unit cost | H41: Install Gateway VM, configure NFS/SMB shares, test connectivity
A42: S3 bucket creation, lifecycle policies, tagging | B42: 1 | C42: Fixed | D42: 500 | E42: One-time AWS console/CLI setup | F42: =B42*D42 -> 500 | G42: qty × Unit cost | H42: 5 buckets × 5 regions, lifecycle rules, Object Lock config
A43: IAM roles, policies, KMS key setup | B43: 1 | C43: Fixed | D43: 500 | E43: One-time security config | F43: =B43*D43 -> 500 | G43: qty × Unit cost | H43: Gateway IAM role, DataSync role, bucket policies, KMS CMKs
A44: Testing, validation & UAT | B44: 1 | C44: Fixed | D44: 3000 | E44: Internal resource time estimate | F44: =B44*D44 -> 3000 | G44: qty × Unit cost | H44: Data integrity checks, retrieval tests, connector smoke tests
A45: HubStor subscription decommission & contract mgmt | B45: 1 | C45: Fixed | D45: 2000 | E45: Legal/admin for contract termination | F45: =B45*D45 -> 2000 | G45: qty × Unit cost | H45: Notice period management, final data verification, sign-off
A46: SUBTOTAL — AWS SETUP COSTS | F46: =SUM(F40:F45) -> 22820.51 | G46: SUM(F40:F45) — sum all setup costs
...

Sheet Risks & Assumptions
A1: RISKS & ASSUMPTIONS — COMPLETE HUBSTOR + AZURE BLOB REPLACEMENT WITH AWS S3
A2: Must be reviewed and signed off before project commencement | Owner = Cloud Architecture Team
A4: KEY ASSUMPTIONS
A5: # | B5: Category | C5: Assumption | D5: Basis / Source | E5: If Wrong — Impact | F5: Owner | G5: Status
A6: A1 | B6: Pricing | C6: AWS list pricing held flat for 3-year model | D6: AWS published list rates March 2026 | E6: Costs could rise — actual savings may be lower | F6: Cloud Arch | G6: Confirmed
A7: A2 | B7: Pricing | C7: HubStor non-storage fee = 34.3% of storage cost (=$9,068÷$26,455) | D7: HubStor Master Report v5 actuals | E7: Ratio may vary monthly — directionally correct | F7: Finance | G7: Confirmed
A8: A3 | B8: Pricing | C8: Azure egress billed at public internet rates (not VPN) | D8: Architecture decision — direct to S3 public endpoint | E8: VPN routing adds AWS transit cost ($0.02/GB) — adds ~$18K | F8: Cloud Arch | G8: Decision required
A9: A4 | B9: Data | C9: All 1,041.7 TiB migrated to AWS (no data deleted pre-migration) | D9: HubStor Master Report v5 — all stors migrated | E9: Smaller dataset = lower migration cost; larger = higher | F9: Programme Mgr | G9: TBC
A10: A5 | B10: Data | C10: Archive avg file size = 500MB (PUT cost sensitivity) | D10: Assumed; actual could range 1MB-2GB (see sensitivity table) | E10: At 1MB avg: PUT cost rises by $45K; at 100MB: negligible | F10: Data Team | G10: Verify before migration
A11: A6 | B11: Data | C11: 5% annual data growth rate | D11: Conservative industry estimate for scientific archives | E11: Higher growth = higher AWS costs but also higher HubStor costs | F11: Data Team | G11: TBC
A12: A7 | B12: Architecture | C12: 5 Storage Gateway VMs required (1 per major site) | D12: Site topology from Connector Details sheet — MWN, WLM, RNO, UK, EU | E12: More sites = higher EC2/EBS cost; fewer = simpler but single-site risk | F12: Cloud Arch | G12: Review with sites
A13: A8 | B13: Architecture | C13: File Gateway (NFS/SMB) replaces all HubStor connectors | D13: HubStor connector list has 17+ connectors — all routed via Gateway | E13: Connector incompatibility = custom integration effort | F13: App Teams | G13: Verify each connector
A14: A9 | B14: Architecture | C14: Direct Connect NOT required — public internet sufficient | D14: Gateway uses HTTPS/TLS; adequate for archive workloads | E14: Bandwidth constraint at peak rehydration may slow retrieval | F14: Network Team | G14: Monitor in pilot
A15: A10 | B15: Migration | C15: Archive rehydration takes 15hr per batch (Azure Standard priority) | D15: Azure documentation — Standard priority SLA | E15: Expedited priority ($0.03/GB extra) available if timeline too slow | F15: Cloud Arch | G15: Plan buffer weeks 3-4
A16: A11 | B16: Migration | C16: DataSync used for US data; Rclone for EU (avoids AWS-specific tooling) | D16: Best practice for cross-cloud migration | E16: Tool failure = manual fallback; add 2-week buffer | F16: Migration Team | G16: TBC
... A21: A16 | B21: Commercial | C21: Wasabi not selected — AWS chosen for S3 API compatibility and GxP compliance | D21: Technical decision | E21: Wasabi at $6.99/TB = slightly cheaper; recalculate if Wasabi selected | F21: Cloud Arch | G21: Decision confirmed
A24: RISK REGISTER
A25: # | B25: Risk Description | C25: Likelihood | D25: Impact | E25: Risk Score | F25: Mitigation | G25: Residual Risk | H25: Owner
A26: R1 | B26: Archive rehydration bottleneck — 882 TiB of Archive data requires up to 15hr rehydration per batch. Migration could take 8-12 weeks for archive tier alone, causing HubStor overlap billing. | C26: HIGH | D26: HIGH | E26: 🔴 CRITICAL | F26: Start archive rehydration in Month 2 immediately. Run parallel batches. Budget for 2 months HubStor overlap (~$71K) in financial model. | G26: MEDIUM | H26: Cloud Arch
A27: R2 | B27: Azure egress cost overrun — Egress calculated at $64,645 but tiered pricing assumes linear volume. Actual rates depend on billing cycle timing. | C27: MEDIUM | D27: MEDIUM | E27: 🟡 MODERATE | F27: Negotiate Azure egress credits for large migration. Pre-announce to Azure account team. Consider doing migration over 2-3 billing cycles to stay in lower tiers. | G27: LOW | H27: Cloud Arch / Azure Rep
A28: R3 | B28: HubStor connector incompatibility — 17+ connectors across multiple sites may not work transparently with S3 File Gateway. DPI connectors (APO-PR-APP-*) may have custom metadata. | C28: MEDIUM | D28: HIGH | E28: 🔴 HIGH | F28: Pilot one connector type per site in Month 2 before full migration. Test DPI connectors specifically. Have HubStor support on standby. | G28: MEDIUM | H28: App Teams / HubStor
A29: R4 | B29: Data integrity loss during migration — File corruption or missing objects during Azure→S3 transfer. | C29: LOW | D29: CRITICAL | E29: 🟡 MODERATE | F29: MD5/ETag checksums validated by DataSync. Run post-migration inventory compare (S3 Inventory vs HubStor report). Do NOT decommission HubStor until 100% verified. | G29: LOW | H29: Migration Team
A30: R5 | B30: AWS Storage Gateway performance under load — Local cache (1TB EBS) may be insufficient for sites with high concurrent archive read requests. | C30: MEDIUM | D30: MEDIUM | E30: 🟡 MODERATE | F30: Monitor cache hit ratio from day 1. Increase EBS cache to 2TB if hit ratio <80%. Pre-warm cache for frequently accessed data. | G30: LOW | H30: Cloud Arch
A31: R6 | B31: Object Lock misconfiguration on GxP data — Incorrect retention period (too short or wrong mode) creates compliance gap. | C31: LOW | D31: CRITICAL | E31: 🟡 MODERATE | F31: Legal/QA review of retention periods before bucket creation. Use Compliance mode (not Governance). Test with non-regulated data first. | G31: LOW | H31: QA/Regulatory/Legal
A32: R7 | B32: Cost model underestimation — AWS S3 Glacier Deep Archive retrieval fees may be higher than estimated if archive access is more frequent than 0.5%/month. | C32: MEDIUM | D32: MEDIUM | E32: 🟡 MODERATE | F32: Monitor S3 retrieval metrics in CloudWatch from Month 1. Set Cost Anomaly Detection alerts at 120% of budget. Review quarterly. | G32: LOW | H32: Cloud Arch / Finance
A33: R8 | B33: HubStor contract lock-in — Contract may require >30 day notice or have early termination penalties. | C33: MEDIUM | D33: HIGH | E33: 🔴 HIGH | F33: Review HubStor contract IMMEDIATELY. If >30 day notice required, adjust timeline. Factor any penalties into migration cost. | G33: MEDIUM | H33: Legal / Finance
A34: R9 | B34: EU data sovereignty breach — Data temporarily routed outside correct region during migration. | C34: LOW | D34: CRITICAL | E34: 🟡 MODERATE | F34: Enforce bucket region from day 1 with SCP (Service Control Policy). No cross-region replication. Use AWS Config rule to alert on region violations. | G34: LOW | H34: Cloud Arch / Legal
A35: R10 | B35: Bandwidth saturation during migration — Simultaneous rehydration + egress from Azure may saturate site/DC internet links. | C35: MEDIUM | D35: MEDIUM | E35: 🟡 MODERATE | F35: Schedule migration transfers outside business hours. Set bandwidth limits in DataSync/Rclone. Start with smallest stor (RMS 914 GiB) as controlled pilot. | G35: LOW | H35: Network Team

Sheet 6-Month Migration Plan
A1: 6-MONTH MIGRATION PLAN — COMPLETE HUBSTOR → AWS S3 REPLACEMENT
A2: Phased approach: Pilot → US Regions → EU Regions → Cutover | Data residency preserved throughout | HubStor runs in parallel until Month 6
A4: PHASE OVERVIEW — TIMELINE AT A GLANCE
A5: Phase | B5: Description | C5: Month 1 | D5: Month 2 | E5: Month 3 | F5: Month 4 | G5: Month 5 | H5: Month 6 | I5: Key Milestone | J5: Owner | K5: Budget Impact ($) | L5: Status
A6: Phase 0 | B6: Foundation & Procurement | C6: ██████ | I6: AWS accounts active, IAM ready, HubStor contract notice served | J6: Cloud Arch | K6: =SUM(F41:F43) -> 0 | L6: Not started
A7: Phase 1 | B7: Pilot Migration (RMS East US) | D7: ██████ | I7: RMS 914 GiB migrated; Gateway tested; data integrity verified | J7: Migration Team | K7: ~$500 AWS costs only | L7: Not started
A8: Phase 2 | B8: US Regions (EastUS2 + WestUS2) | E8: ██████ | I8: 294 TiB US data migrated; US sites cut over to S3 Gateway | J8: Migration Team | K8: =H17*0.27 -> 0 | L8: Not started
A9: Phase 3 | B9: EU UK Region (UKSouth) | F9: ██████ | I9: 374 TiB UK data migrated; UK sites cut over | J9: Migration Team | K9: =H17*0.35 -> 0 | L9: Not started
A10: Phase 4 | B10: EU Continent (WestEurope + Germany) | G10: ██████ | I10: 398 TiB EU/DE data migrated; all EU sites cut over | J10: Migration Team | K10: =H17*0.38 -> 0 | L10: Not started
A11: Phase 5 | B11: Cutover, Decommission & Optimisation | H11: ██████ | I11: HubStor subscription cancelled; zero Azure Blob spend | J11: Cloud Arch / Finance | K11: First full month saving realised | L11: Not started
A13: PHASE 0 — FOUNDATION & PROCUREMENT (Month 1: Weeks 1-4)
A14: Week | B14: Category | C14: Task | D14: Owner | E14: Detail / Notes | F14: Success Criteria
A15: Week 1 | B15: Commercial | C15: Review and serve HubStor contract termination notice (verify notice period) | D15: Legal / Finance | E15: Notice period clock starts. If >30 days, adjust plan. | F15: CONTRACT NOTICE SERVED
A16: Week 1 | B16: AWS Setup | C16: Create AWS accounts per region (us-east-1, us-west-2, eu-west-2, eu-west-1, eu-central-1) | D16: Cloud Arch | E16: 5 AWS accounts or 1 org with SCPs per region | F16: Accounts active
A17: Week 1 | B17: AWS Setup | C17: Configure IAM: DataSync role, Gateway role, S3 bucket policies, KMS CMKs (1 per region) | D17: Cloud Arch | E17: All permissions least-privilege; tested with CLI | F17: IAM complete
A18: Week 2 | B18: AWS Setup | C18: Create S3 buckets with naming convention, Object Lock (Compliance mode), versioning policy | D18: Cloud Arch | E18: Bucket policy blocks public access; Object Lock enabled on GxP buckets | F18: Buckets created
A19: Week 2 | B19: AWS Setup | C19: Configure S3 lifecycle rules: Archive→Glacier Deep Archive on upload; Cool→Standard-IA | D19: Cloud Arch | E19: Lifecycle rules prevent objects landing in wrong tier | F19: Rules active
A20: Week 2 | B20: Monitoring | C20: Deploy CloudWatch dashboards: cost, storage usage, Gateway health, DataSync job status | D20: Cloud Arch | E20: Alerts configured for 120% budget threshold | F20: Dashboards live
A21: Week 3 | B21: Network | C21: Gateway VM deployment — install on-prem at WLM (pilot site). Configure NFS/SMB share | D21: Network + Cloud | E21: VM: m5.xlarge compatible VM on-prem. Attach 1TB EBS cache. Test HTTPS to S3. | F21: WLM Gateway online
A22: Week 3 | B22: Network | C22: Configure AWS VPC Gateway Endpoint for S3 (free — eliminates NAT Gateway fees if EC2 used) | D22: Cloud Arch | E22: Endpoint policy restricts access to specific buckets | F22: VPC endpoint active
A23: Week 4 | B23: Testing | C23: End-to-end connectivity test: write test file via Gateway → verify in S3 bucket → retrieve | D23: Migration Team | E23: Checksum match confirms data integrity path | F23: E2E test PASSED
A24: Week 4 | B24: Documentation | C24: Finalise migration runbook per site. DataSync job scripts prepared. Rollback plan documented | D24: Migration Team | E24: Runbook peer-reviewed | F24: Runbook signed off
A27: PHASE 1 — PILOT MIGRATION: RMS EAST US FILES (Month 2: ~914 GiB)
A28: Week | B28: Category | C28: Task | D28: Owner | E28: Detail / Notes | F28: Success Criteria
A29: Week 5 | B29: Migration | C29: Configure AWS DataSync: source=WLM-PR-FIL-05 Azure Blob, dest=S3 us-east-1 bucket | D29: Migration Team | E29: 3 DataSync tasks (3 connectors); --storage-class=STANDARD_IA for RMS data | F29: DataSync jobs configured
A30: Week 5 | B30: Migration | C30: Start DataSync transfer. Monitor CloudWatch for transfer rate, errors, throughput | D30: Migration Team | E30: Expected: ~200GB/hr → 914 GiB ≈ 5 hours. Run overnight. | F30: Transfer started
A31: Week 6 | B31: Validation | C31: Post-transfer: S3 Inventory report vs HubStor export — compare object counts and sizes | D31: Migration Team | E31: 100% object count match required before proceeding | F31: Integrity VERIFIED
A32: Week 6 | B32: Validation | C32: Retrieval test: retrieve 5 random files via S3 Gateway share. Verify content matches | D32: App Teams | E32: All 5 files open correctly; no corruption | F32: Retrieval PASSED
A33: Week 6 | B33: Cutover | C33: Update WLM-RMS connector to point to S3 File Gateway NFS share (change target path only) | D33: App Teams / Network | E33: Connector writes to S3 from this point; reads via Gateway cache | F33: Connector switched
A34: Week 7 | B34: Monitoring | C34: Monitor RMS connector for 1 week: write speed, retrieval latency, error rate | D34: Cloud Arch | E34: Target: <5s for cached reads; <30min for uncached archive fetch | F34: 1-week soak PASS
A35: Week 8 | B35: Review | C35: Pilot retrospective: document lessons, adjust runbook, confirm Phase 2 go/no-go | D35: Programme Mgr | E35: Signed go/no-go decision gate | F35: GO/NO-GO DECISION
A38: PHASE 2 — US REGIONS: EastUS2 + WestUS2 (Month 3: ~294 TiB)
A39: Week | B39: Category | C39: Task | D39: Owner | E39: Detail / Notes | F39: Success Criteria
A40: Week 9 | B40: Migration | C40: Begin archive rehydration for Safety Assessment East US (119 TiB archive). Submit rehydration job. | D40: Migration Team | E40: Azure Standard rehydration = up to 15hr. Batch by stor group. | F40: Rehydration started
A41: Week 9 | B41: Migration | C41: Deploy Gateway VM at MWN site (Safety Assessment). Configure connectors. | D41: Cloud Arch | E41: Mirror WLM setup. Same EBS cache size. Test connectivity. | F41: MWN Gateway ready
A42: Week 9 | B42: Migration | C42: Deploy Gateway VM at RNO site (Safety Assessment West). Configure connectors. | D42: Cloud Arch | E42: RNO covers WestUS2 data. | F42: RNO Gateway ready
A43: Week 10 | B43: Migration | C43: Start DataSync jobs: Microbial East US (25 TiB), RMS sub-stores remaining | D43: Migration Team | E43: Run overnight. Monitor DataSync CloudWatch dashboard. | F43: Microbial migrated
A44: Week 10 | B44: Migration | C44: Start DataSync jobs: Safety Assessment East US (after rehydration completes) | D44: Migration Team | E44: 122 TiB total. Largest US store. May take 2-3 nights. | F44: SA East migrated
A45: Week 11 | B45: Migration | C45: Start DataSync jobs: Safety Assessment West US (72 TiB WestUS2 data) | D45: Migration Team | E45: RNO connector data. Run over 2 nights. | F45: SA West migrated
A46: Week 11 | B46: Validation | C46: S3 Inventory cross-check for all US stores. Fix any gaps. | D46: Migration Team | E46: Zero discrepancy required | F46: US inventory matched
...

Sheet Financial Model (Jun26-Dec30)
A1: FINANCIAL MODEL — Jun 2026 to Dec 2030 | Migration Period + 4-Year AWS TCO
A2: Jul 1 – Dec 31 2026: RAMPED migration — AWS grows as gateways come online, migration cost distributed by activity type | HubStor reduces from Oct as Azure regions deleted | Jan 2027–Dec 2030: AWS only
A4: MODEL INPUTS — all linked to Assumptions & Cost Comparison (change values there)
A5: HubStor + Azure monthly cost (current actuals) | B5: =Assumptions!C65 -> 35523.12
A6: AWS Total monthly — storage + Gateway appliance + all infra | B6: ='Cost Comparison'!B37 -> 6196.0458
A7: One-time migration cost (total) | B7: ='Migration Plan & Costs'!C60 -> 121370.23
A8: Annual data growth rate (applied from 2028 onwards) | B8: =Assumptions!C64 -> 0.05
A9: Monthly saving once fully on AWS (B5 − B6) | B9: =B5-B6 -> 29327.074
A10: Migration period (months: Jun–Dec 2026) | B10: 6
A11: AWS costs already paid during migration overlap (Jul–Dec 2026) | B11: =SUM(D17:D22) -> 25007.64 | C11: Sum of AWS ramp-up costs during migration (Jul–Dec). These must also be recovered from savings.
A12: Payback — months from Jan 2027 (migration cost + AWS overlap ÷ monthly saving) | B12: =(B7+B11)/B9 -> 4.9912198 | C12: =TEXT((B7+B11)/B9,"0.0")&" months from Jan 2027 | Formula: (migration cost + Phase 1 AWS overlap) ÷ monthly saving | ~May 2027" -> 5.0 months from Jan 2027 | Formula: (migration cost + Phase 1 AWS overlap) ÷ monthly saving | ~May 2027
A14: PHASE 1 — MIGRATION PERIOD (Jul 1, 2026 – Dec 31, 2026) | AWS ramps up month by month | HubStor steps down as Azure regions deleted from Oct
A15: Migration cost distributed across 6 months by activity: data-transfer costs follow the data ramp | gateway installs match each site go-live | testing & decommission back-loaded to Nov–Dec
A16: # | B16: Calendar Month | C16: HubStor + Azure ($) [ramps ↓ from Oct] | D16: AWS Total ($) [ramps ↑ all 6 months] | E16: Combined Spend ($) | F16: Migration Cost ($) [distributed by activity] | G16: Migration Cost — What's included | H16: Net Cumulative Saving ($)
A17: 1 | B17: Jul 2026 | C17: 35523.12 | D17: 1429.61 | E17: =C17+D17+F17 -> 61006.78 | F17: 24054.05 | G17: AWS: 1 gateway online (US-East). 20% of data migrated to S3. /// Mig cost: S3/IAM setup + DataSync: 20% of data transfer costs + US-East gateway install | H17: =-SUM(C17:C17)-SUM(F17:F17) -> -59577.17
A18: 2 | B18: Aug 2026 | C18: 35523.12 | D18: 2440.82 | E18: =C18+D18+F18 -> 55316.97 | F18: 17353.03 | G18: AWS: 2 gateways live (US-East + US-West). 35% migrated. /// Mig cost: DataSync: 15% of data transfer costs + US-West gateway install | H18: =-SUM(C17:C18)-SUM(F17:F18) -> -112453.32
A19: 3 | B19: Sep 2026 | C19: 35523.12 | D19: 3812.83 | E19: =C19+D19+F19 -> 67891.01 | F19: 28555.06 | G19: AWS: 3 gateways live (US + UK). 60% migrated. /// Mig cost: DataSync: 25% of data transfer costs (largest batch — UK 374 TiB) + UK gateway install | H19: =-SUM(C17:C19)-SUM(F17:F19) -> -176531.5
A20: 4 | B20: Oct 2026 | C20: 31565.7 | D20: 5004.44 | E20: =C20+D20+F20 -> 59854.19 | F20: 23284.05 | G20: AWS: 4 gateways live (US + UK + EU-NL). 80% migrated. /// Mig cost: DataSync: 20% of data transfer costs + EU-NL gateway install + testing starts | H20: =-SUM(C17:C20)-SUM(F17:F20) -> -231381.25
A21: 5 | B21: Nov 2026 | C21: 11272.55 | D21: 6123.89 | E21: =C21+D21+F21 -> 32378.87 | F21: 14982.43 | G21: AWS: All 5 gateways at full capacity. 98% migrated. /// Mig cost: DataSync: 12% of data transfer costs + EU-DE gateway install + testing | H21: =-SUM(C17:C21)-SUM(F17:F21) -> -257636.23
A22: 6 | B22: Dec 2026 | C22: 1000 | D22: 6196.05 | E22: =C22+D22+F22 -> 20337.67 | F22: 13141.62 | G22: Final 8% data costs + testing/validation + HubStor decommission ($2,200) | H22: =-SUM(C17:C22)-SUM(F17:F22) -> -271777.85
A23: 6 mo | B23: MIGRATION TOTAL Jul–Dec 2026 | C23: =SUM(C15:C20) -> 138135.06 | D23: =SUM(D15:D20) -> 12687.7 | E23: =SUM(E17:E22) -> 296785.49 | F23: =SUM(F15:F20) -> 93246.19 | G23: ↑ Total investment = migration cost ($121,370) + AWS overlap ($24,791) = $146,161 | Payback ~5 months from Jan 2027 ≈ Jun 2027 | H23: =H22 -> -271777.85
A24: Migration cost breakdown: Jul $24,054 (setup+20% data) | Aug $17,353 (15% data) | Sep $28,555 (25% data — UK batch) | Oct $23,284 (20% data) | Nov $14,982 (12% data+testing) | Dec $13,142 (8% data+decomm) → Total = $121,370
A26: PHASE 2 — AWS ONLY (Jan 2027 – Dec 2030) | HubStor fully terminated. Azure Blob = $0. Pure AWS spend.
A27: AWS storage grows with data volume: 5% per year from 2028. Column E = monthly saving vs old HubStor baseline ($35,523). Column H = running net cumulative saving carried forward from Dec 2026.
A28: # | B28: Calendar Month | C28: HubStor + Azure ($) [= $0 from Jan 2027] | D28: AWS Total ($) | E28: Monthly Saving vs HubStor ($) | F28: Cumul. Saving since Jan 2027 ($) | G28: — | H28: Net Cumulative Saving ($)
A29: 8 | B29: Jan 2027 | C29: 0 | D29: =$B$6 -> 6196.0458 | E29: =$B$5-$B$6 -> 29327.074 | F29: =SUM($E$27:E27) -> 0 | G29: 0 | H29: =H23+E29 -> -242450.78
A30: 9 | B30: Feb 2027 | C30: 0 | D30: =$B$6 -> 6196.0458 | E30: =$B$5-$B$6 -> 29327.074 | F30: =SUM($E$27:E28) -> 0 | G30: 0 | H30: =H29+E30 -> -213123.7
A31: 10 | B31: Mar 2027 | C31: 0 | D31: =$B$6 -> 6196.0458 | E31: =$B$5-$B$6 -> 29327.074 | F31: =SUM($E$27:E29) -> 29327.074 | G31: 0 | H31: =H30+E31 -> -183796.63
A32: 11 | B32: Apr 2027 | C32: 0 | D32: =$B$6 -> 6196.0458 | E32: =$B$5-$B$6 -> 29327.074 | F32: =SUM($E$27:E30) -> 58654.148 | G32: 0 | H32: =H31+E32 -> -154469.55
A33: 12 | B33: May 2027 | C33: 0 | D33: =$B$6 -> 6196.0458 | E33: =$B$5-$B$6 -> 29327.074 | F33: =SUM($E$27:E31) -> 87981.223 | G33: 0 | H33: =H32+E33 -> -125142.48
A34: 13 | B34: Jun 2027 | C34: 0 | D34: =$B$6 -> 6196.0458 | E34: =$B$5-$B$6 -> 29327.074 | F34: =SUM($E$27:E32) -> 117308.3 | G34: 0 | H34: =H33+E34 -> -95815.405
A35: 14 | B35: Jul 2027 | C35: 0 | D35: =$B$6 -> 6196.0458 | E35: =$B$5-$B$6 -> 29327.074 | F35: =SUM($E$27:E33) -> 146635.37 | G35: 0 | H35: =H34+E35 -> -66488.33
A36: 15 | B36: Aug 2027 | C36: 0 | D36: =$B$6 -> 6196.0458 | E36: =$B$5-$B$6 -> 29327.074 | F36: =SUM($E$27:E34) -> 175962.45 | G36: 0 | H36: =H35+E36 -> -37161.256
A37: 16 | B37: Sep 2027 | C37: 0 | D37: =$B$6 -> 6196.0458 | E37: =$B$5-$B$6 -> 29327.074 | F37: =SUM($E$27:E35) -> 205289.52 | G37: 0 | H37: =H36+E37 -> -7834.1819
A38: 17 | B38: Oct 2027 | C38: 0 | D38: =$B$6 -> 6196.0458 | E38: =$B$5-$B$6 -> 29327.074 | F38: =SUM($E$27:E36) -> 234616.59 | G38: 0 | H38: =H37+E38 -> 21492.892
A39: 18 | B39: Nov 2027 | C39: 0 | D39: =$B$6 -> 6196.0458 | E39: =$B$5-$B$6 -> 29327.074 | F39: =SUM($E$27:E37) -> 263943.67 | G39: 0 | H39: =H38+E39 -> 50819.967
A40: 19 | B40: Dec 2027 | C40: 0 | D40: =$B$6 -> 6196.0458 | E40: =$B$5-$B$6 -> 29327.074 | F40: =SUM($E$27:E38) -> 293270.74 | G40: 0 | H40: =H39+E40 -> 80147.041
A41: 20 | B41: Jan 2028 | C41: 0 | D41: =$B$6*(1+$B$8) -> 6505.8481 | E41: =$B$5-$B$6*(1+$B$8) -> 29017.272 | F41: =SUM($E$27:E39) -> 322597.82 | G41: 0 | H41: =H40+E41 -> 109164.31
A42: 21 | B42: Feb 2028 | C42: 0 | D42: =$B$6*(1+$B$8) -> 6505.8481 | E42: =$B$5-$B$6*(1+$B$8) -> 29017.272 | F42: =SUM($E$27:E40) -> 351924.89 | G42: 0 | H42: =H41+E42 -> 138181.58
A43: 22 | B43: Mar 2028 | C43: 0 | D43: =$B$6*(1+$B$8) -> 6505.8481 | E43: =$B$5-$B$6*(1+$B$8) -> 29017.272 | F43: =SUM($E$27:E41) -> 380942.16 | G43: 0 | H43: =H42+E43 -> 167198.86
...

Sheet Architecture & Connectivity
A1: AWS S3 TARGET ARCHITECTURE — CONNECTIVITY & ACCESS DESIGN
A2: Full HubStor replacement | S3 File Gateway replaces all HubStor connectors | Data residency preserved per region
A4: STORAGE GATEWAY — HOW SITES CONNECT TO S3 (replaces HubStor connector agents)
A5: Pattern | B5: AWS S3 File Gateway (NFS/SMB shares) → replaces every HubStor connector agent at each site. S3-compatible. No application changes needed.
A6: What it is | B6: A VM (VMware / Hyper-V / KVM) deployed on-prem at each site. Presents NFS or SMB shares to local applications. Data written to shares is automatically uploaded to S3 as objects with compression and encryption.
A7: Archiving flow | B7: Application saves file → File Gateway share → Gateway caches locally → Compresses & uploads to S3 bucket (correct storage class via lifecycle rule) → File stays accessible via share (cached read).
A8: Retrieval flow | B8: User requests file from Gateway share → Gateway checks local 1TB EBS cache → If cached: instant return → If not cached: fetches from S3 (Standard-IA: ms; Glacier IR: ms; Deep Archive: restore first ~12-48hr) → Returns file.
A9: Sites & VMs | B9: 5 Gateway VMs required: • WLM (EastUS2) → us-east-1 • RNO (WestUS2) → us-west-2 • UK sites (UKSouth) → eu-west-2 • NL/EU sites (WestEurope) → eu-west-1 • DE site (GermanyWestCentral) → eu-central-1
A10: HubStor connectors replaced | B10: All 17+ DPI connectors (APO-PR-APP-*), NAS connectors (MWN-PR-FIL-01, WLM-PR-FIL-05), and test connectors replaced by gateway shares. One Gateway per site serves all connectors at that site.
A11: Migration tool | B11: AWS DataSync for bulk one-time migration (Azure Blob → S3). DataSync handles checksums, retry, parallelism. Post-migration: Gateway handles all incremental writes; DataSync not needed.
A13: S3 BUCKET STRATEGY
A14: Bucket per region (5 buckets) | B14: us-east-1: company-archive-us-east / us-west-2: company-archive-us-west / eu-west-2: company-archive-uk / eu-west-1: company-archive-eu / eu-central-1: company-archive-de
A15: Prefix / key structure | B15: s3://company-archive-{region}/{site-code}/{stor-name}/{year}/{month}/{filename} e.g., s3://company-archive-uk/CRP/EarlyDiscovery/2024/03/sample.raw
A16: Storage class mapping | B16: Standard/Hot → S3 Standard | Cool → S3 Standard-IA (lifecycle Day 0) | Cold → S3 Glacier Instant Retrieval | Archive → S3 Glacier Deep Archive (PUT directly via --storage-class)
A17: Lifecycle rules | B17: Lifecycle rule 1: Objects with tag tier=cool → Standard-IA immediately. Rule 2: Objects with tag tier=archive → Glacier Deep Archive immediately. Rule 3: Incomplete multipart uploads → abort after 7 days.
A18: Object Lock (GxP data) | B18: Enable S3 Object Lock in Compliance mode on buckets holding GxP-regulated data (Safety Assessment, Microbial). Retention period = defined by QA/Regulatory team. Objects cannot be deleted or modified during retention.
A19: Versioning | B19: Enable ONLY on compliance/GxP buckets. Do NOT enable on pure archive buckets (versioning doubles storage cost for every overwrite).
A20: Encryption | B20: SSE-S3 (AES-256) at zero extra cost as baseline. Upgrade to SSE-KMS for GxP data requiring audit trail of key access. 1 KMS CMK per region = $5/month total.
A21: VPC Gateway Endpoint | B21: Deploy free S3 VPC Gateway Endpoint in each AWS region to route S3 traffic within AWS backbone — eliminates NAT Gateway data processing charges if any EC2-based processing is added later.
A23: CONNECTIVITY OPTIONS
A24: Option A — HTTPS/TLS (Recommended, chosen for this design) | B24: Gateway VM uploads to S3 public endpoint over port 443 (HTTPS). Data is encrypted in transit (TLS 1.2+). No additional cost. All current sites have reliable internet. This is the chosen architecture.
A25: Option B — AWS Site-to-Site VPN (optional add-on) | B25: ~$0.05/hr per VPN connection = $36/mo. Use if security policy requires private connectivity. Can be added after cutover. Transit cost ~$0.01/GB within AWS. NOT required for launch.
A26: Option C — AWS Direct Connect (optional premium) | B26: Dedicated 1Gbps circuit ~$200-500/mo port cost. Use only if bandwidth becomes a demonstrated bottleneck after 3 months on Option A. Overkill for archive workloads.
A27: Recommendation | B27: Launch with Option A. Monitor Gateway CloudWatch metric WriteBytesPerSecond. If consistently >50MB/s sustained and latency is causing issues, evaluate Option B as next step.
A29: REGION MAPPING — AZURE → AWS (data residency preserved)
A30: Azure EastUS2 (Virginia, USA) | B30: → AWS us-east-1 (N. Virginia) | Sites: MWN, WLM | Safety Assessment East, Microbial, RMS
A31: Azure WestUS2 (Washington, USA) | B31: → AWS us-west-2 (Oregon) | Sites: RNO | Safety Assessment West
A32: Azure UKSouth (London, UK) | B32: → AWS eu-west-2 (London) | Sites: CRP, HAR, PTH, EDI | UK data stays in UK ✓
A33: Azure WestEurope (Amsterdam, NL) | B33: → AWS eu-west-1 (Ireland) | Sites: LEI, HER, GRO, KUO, SZG, FRE, LYO, EVR | EU data stays in EU ✓
A34: Azure GermanyWestCentral (Frankfurt) | B34: → AWS eu-central-1 (Frankfurt) | Sites: FRI | German data stays in Germany (GDPR) ✓
A35: GDPR / Data Sovereignty | B35: No data crosses borders. UK data: eu-west-2 (London). German data: eu-central-1 (Frankfurt). All EU data in EU. S3 bucket region is enforced by SCP (Service Control Policy) blocking bucket creation in wrong regions.
